Workbook

Sheet 日付
A1: 44329.893 | B1: =TODAY() -> 46029 | D1: 先月月初 | E1: 当月月初 | F1: 翌月月初
D2: =DATE(YEAR(A$1+(7-WEEKDAY(A$1,2)+1)), MONTH(A$1+(7-WEEKDAY(A$1,2)+1))-1, 1) -> 44287 | E2: =DATE(YEAR(A$1+(7-WEEKDAY(A$1,2)+1)), MONTH(A$1+(7-WEEKDAY(A$1,2)+1)), 1) -> 44317 | F2: =DATE(YEAR(A$1+(7-WEEKDAY(A$1,2)+1)), MONTH(A$1+(7-WEEKDAY(A$1,2)+1))+1, 1) -> 44348

Sheet Weekly(H)
B2: 週間目標 | F2: =YEAR('日付'!A$1+(7-WEEKDAY('日付'!A$1,2)+1))&"年 "&MONTH('日付'!A$1+(7-WEEKDAY('日付'!A$1,2)+1))&"月 第"&WEEKNUM(YEAR('日付'!A$1+(7-WEEKDAY('日付'!A$1,2)+1))&"/"&MONTH('日付'!A$1+(7-WEEKDAY('日付'!A$1,2)+1))&"/"&DAY('日付'!A$1+(7-WEEKDAY('日付'!A$1,2)+1)),2)-WEEKNUM(YEAR('日付'!A$1+(7-WEEKDAY('日付'!A$1,2)+1))&"/"&MONTH('日付'!A$1+(7-WEEKDAY('日付'!A$1,2)+1))&"/1",1)+1&"週(第"&WEEKNUM(YEAR('日付'!A$1+(7-WEEKDAY('日付'!A$1,2)+1))&"/"&MONTH('日付'!A$1+(7-WEEKDAY('日付'!A$1,2)+1))&"/"&DAY('日付'!A$1+(7-WEEKDAY('日付'!A$1,2)+1)),2)&"週)" -> 2021年 5月 第4週(第21週)
F4: 今月のテーマ
B8: ルーティーン行動 | AF8: 月 | AG8: 火 | AH8: 水 | AI8: 木 | AJ8: 金 | AK8: 土 | AL8: 日
B9: 1
B10: 2
B11: 3
B12: 4
B13: 5
B14: 6
B16: 役割と重点タスク
B17: 役割1：自分自身
B18: 目標1：身体 | U18: 目標2：社会・情緒
B21: 目標3：知性 | U21: 目標4：精神
B25: 役割2：トレーダー
B26: 目標1： | U26: 目標2：
B29: 目標3： | U29: 目標4：
B33: 役割3：
B34: 目標1： | U34: 目標2：
B37: 目標3： | U37: 目標4：
B41: 役割4：
B42: 目標1： | U42: 目標2：
B45: 目標3： | U45: 目標4：
B49: 今週の振り返り
B50: 良かったこと | U50: 課題・改善
AG62: 利損：
B66: =MONTH('日付'!A$1+(7-WEEKDAY('日付'!A$1,2)+6)) -> 5 | D66: 土 | E66: 今日の一言：
B69: =DAY('日付'!A$1+(7-WEEKDAY('日付'!A$1,2)+6)) -> 22
AG70: 利損：
AL71: =IFERROR(VLOOKUP('日付'!A$1+(7-WEEKDAY('日付'!A$1,2)+6),'祝日一覧'!A:B,2,false),"")
B72: =MONTH('日付'!A$1+(7-WEEKDAY('日付'!A$1,2)+7)) -> 5 | D72: 日 | E72: 今日の一言：
B75: =DAY('日付'!A$1+(7-WEEKDAY('日付'!A$1,2)+7)) -> 23
AG76: 利損：
AL77: =IFERROR(VLOOKUP('日付'!A$1+(7-WEEKDAY('日付'!A$1,2)+7),'祝日一覧'!A:B,2,false),"")
B79: Note:
B120: □ | K120: □ | T120: □ | AC120: □
B122: □ | K122: □ | T122: □ | AC122: □
B124: □ | K124: □ | T124: □ | AC124: □
B126: □ | K126: □ | T126: □ | AC126: □
C130: =MONTH('日付'!$D$2) -> 4 | E130: =IF(DAY('日付'!$D$2-WEEKDAY('日付'!$D$2,2)+1)<=7,DAY('日付'!$D$2-WEEKDAY('日付'!$D$2,2)+1),"") | F130: =IF(DAY('日付'!$D$2-WEEKDAY('日付'!$D$2,2)+2)<=7,DAY('日付'!$D$2-WEEKDAY('日付'!$D$2,2)+2),"") | G130: =IF(DAY('日付'!$D$2-WEEKDAY('日付'!$D$2,2)+3)<=7,DAY('日付'!$D$2-WEEKDAY('日付'!$D$2,2)+3),"") | H130: =IF(DAY('日付'!$D$2-WEEKDAY('日付'!$D$2,2)+4)<=7,DAY('日付'!$D$2-WEEKDAY('日付'!$D$2,2)+4),"") -> 1 | I130: =IF(DAY('日付'!$D$2-WEEKDAY('日付'!$D$2,2)+5)<=7,DAY('日付'!$D$2-WEEKDAY('日付'!$D$2,2)+5),"") -> 2 | J130: =IF(DAY('日付'!$D$2-WEEKDAY('日付'!$D$2,2)+6)<=7,DAY('日付'!$D$2-WEEKDAY('日付'!$D$2,2)+6),"") -> 3 | K130: =IF(DAY('日付'!$D$2-WEEKDAY('日付'!$D$2,2)+7)<=7,DAY('日付'!$D$2-WEEKDAY('日付'!$D$2,2)+7),"") -> 4 | O130: =MONTH('日付'!$E$2) -> 5 | Q130: =IF(DAY('日付'!$E$2-WEEKDAY('日付'!$E$2,2)+1)<=7,DAY('日付'!$E$2-WEEKDAY('日付'!$E$2,2)+1),"") | R130: =IF(DAY('日付'!$E$2-WEEKDAY('日付'!$E$2,2)+2)<=7,DAY('日付'!$E$2-WEEKDAY('日付'!$E$2,2)+2),"") | S130: =IF(DAY('日付'!$E$2-WEEKDAY('日付'!$E$2,2)+3)<=7,DAY('日付'!$E$2-WEEKDAY('日付'!$E$2,2)+3),"") | T130: =IF(DAY('日付'!$E$2-WEEKDAY('日付'!$E$2,2)+4)<=7,DAY('日付'!$E$2-WEEKDAY('日付'!$E$2,2)+4),"") | U130: =IF(DAY('日付'!$E$2-WEEKDAY('日付'!$E$2,2)+5)<=7,DAY('日付'!$E$2-WEEKDAY('日付'!$E$2,2)+5),"") | V130: =IF(DAY('日付'!$E$2-WEEKDAY('日付'!$E$2,2)+6)<=7,DAY('日付'!$E$2-WEEKDAY('日付'!$E$2,2)+6),"") -> 1 | W130: =IF(DAY('日付'!$E$2-WEEKDAY('日付'!$E$2,2)+7)<=7,DAY('日付'!$E$2-WEEKDAY('日付'!$E$2,2)+7),"") -> 2 | AB130: =MONTH('日付'!$F$2) -> 6 | AD130: =IF(DAY('日付'!$F$2-WEEKDAY('日付'!$F$2,2)+1)<=7,DAY('日付'!$F$2-WEEKDAY('日付'!$F$2,2)+1),"") | AE130: =IF(DAY('日付'!$F$2-WEEKDAY('日付'!$F$2,2)+2)<=7,DAY('日付'!$F$2-WEEKDAY('日付'!$F$2,2)+2),"") -> 1 | AF130: =IF(DAY('日付'!$F$2-WEEKDAY('日付'!$F$2,2)+3)<=7,DAY('日付'!$F$2-WEEKDAY('日付'!$F$2,2)+3),"") -> 2 | AG130: =IF(DAY('日付'!$F$2-WEEKDAY('日付'!$F$2,2)+4)<=7,DAY('日付'!$F$2-WEEKDAY('日付'!$F$2,2)+4),"") -> 3 | AH130: =IF(DAY('日付'!$F$2-WEEKDAY('日付'!$F$2,2)+5)<=7,DAY('日付'!$F$2-WEEKDAY('日付'!$F$2,2)+5),"") -> 4 | AI130: =IF(DAY('日付'!$F$2-WEEKDAY('日付'!$F$2,2)+6)<=7,DAY('日付'!$F$2-WEEKDAY('日付'!$F$2,2)+6),"") -> 5 | AJ130: =IF(DAY('日付'!$F$2-WEEKDAY('日付'!$F$2,2)+7)<=7,DAY('日付'!$F$2-WEEKDAY('日付'!$F$2,2)+7),"") -> 6
E131: =DAY('日付'!$D$2-WEEKDAY('日付'!$D$2,2)+8) -> 5 | F131: =DAY('日付'!$D$2-WEEKDAY('日付'!$D$2,2)+9) -> 6 | G131: =DAY('日付'!$D$2-WEEKDAY('日付'!$D$2,2)+10) -> 7 | H131: =DAY('日付'!$D$2-WEEKDAY('日付'!$D$2,2)+11) -> 8 | I131: =DAY('日付'!$D$2-WEEKDAY('日付'!$D$2,2)+12) -> 9 | J131: =DAY('日付'!$D$2-WEEKDAY('日付'!$D$2,2)+13) -> 10 | K131: =DAY('日付'!$D$2-WEEKDAY('日付'!$D$2,2)+14) -> 11 | Q131: =DAY('日付'!$E$2-WEEKDAY('日付'!$E$2,2)+8) -> 3 | R131: =DAY('日付'!$E$2-WEEKDAY('日付'!$E$2,2)+9) -> 4 | S131: =DAY('日付'!$E$2-WEEKDAY('日付'!$E$2,2)+10) -> 5 | T131: =DAY('日付'!$E$2-WEEKDAY('日付'!$E$2,2)+11) -> 6 | U131: =DAY('日付'!$E$2-WEEKDAY('日付'!$E$2,2)+12) -> 7 | V131: =DAY('日付'!$E$2-WEEKDAY('日付'!$E$2,2)+13) -> 8 | W131: =DAY('日付'!$E$2-WEEKDAY('日付'!$E$2,2)+14) -> 9 | AD131: =DAY('日付'!$F$2-WEEKDAY('日付'!$F$2,2)+8) -> 7 | AE131: =DAY('日付'!$F$2-WEEKDAY('日付'!$F$2,2)+9) -> 8 | AF131: =DAY('日付'!$F$2-WEEKDAY('日付'!$F$2,2)+10) -> 9 | AG131: =DAY('日付'!$F$2-WEEKDAY('日付'!$F$2,2)+11) -> 10 | AH131: =DAY('日付'!$F$2-WEEKDAY('日付'!$F$2,2)+12) -> 11 | AI131: =DAY('日付'!$F$2-WEEKDAY('日付'!$F$2,2)+13) -> 12 | AJ131: =DAY('日付'!$F$2-WEEKDAY('日付'!$F$2,2)+14) -> 13
...

Sheet Monthly
E2: =YEAR('日付'!A1) -> 2021 | H2: 年 | J2: =MONTH('日付'!A1) -> 5 | L2: 月
A4: chk | C4: Priority | F4: プライベート | U4: chk | W4: Priority | Z4: ビジネス
A5: □ | U5: □
A7: □ | U7: □
A9: □ | U9: □
A11: □ | U11: □
A13: □ | U13: □
A15: □ | U15: □
A17: □ | U17: □
A19: □ | U19: □
A21: □ | U21: □
A23: □ | U23: □
A25: □ | U25: □
A27: □ | U27: □
... A61: □ | U61: □
D66: THU | M66: FRI | V66: SAT | AE66: SUN
C68: =DAY('日付'!$E$2-WEEKDAY('日付'!$E$2,2)+4) -> 29 | L68: =DAY('日付'!$E$2-WEEKDAY('日付'!$E$2,2)+5) -> 30 | U68: =DAY('日付'!$E$2-WEEKDAY('日付'!$E$2,2)+6) -> 1 | AD68: =DAY('日付'!$E$2-WEEKDAY('日付'!$E$2,2)+7) -> 2
K76: =IFERROR(VLOOKUP('日付'!$E$2-WEEKDAY('日付'!$E$2,2)+4,'祝日一覧'!$A:$B,2,false),"") -> 昭和の日 | T76: =IFERROR(VLOOKUP('日付'!$E$2-WEEKDAY('日付'!$E$2,2)+5,'祝日一覧'!$A:$B,2,false),"") | AC76: =IFERROR(VLOOKUP('日付'!$E$2-WEEKDAY('日付'!$E$2,2)+6,'祝日一覧'!$A:$B,2,false),"") | AL76: =IFERROR(VLOOKUP('日付'!$E$2-WEEKDAY('日付'!$E$2,2)+7,'祝日一覧'!$A:$B,2,false),"")
C77: =DAY('日付'!$E$2-WEEKDAY('日付'!$E$2,2)+11) -> 6 | L77: =DAY('日付'!$E$2-WEEKDAY('日付'!$E$2,2)+12) -> 7 | U77: =DAY('日付'!$E$2-WEEKDAY('日付'!$E$2,2)+13) -> 8 | AD77: =DAY('日付'!$E$2-WEEKDAY('日付'!$E$2,2)+14) -> 9
K85: =IFERROR(VLOOKUP('日付'!$E$2-WEEKDAY('日付'!$E$2,2)+11,'祝日一覧'!$A:$B,2,false),"") | T85: =IFERROR(VLOOKUP('日付'!$E$2-WEEKDAY('日付'!$E$2,2)+12,'祝日一覧'!$A:$B,2,false),"") | AC85: =IFERROR(VLOOKUP('日付'!$E$2-WEEKDAY('日付'!$E$2,2)+13,'祝日一覧'!$A:$B,2,false),"") | AL85: =IFERROR(VLOOKUP('日付'!$E$2-WEEKDAY('日付'!$E$2,2)+14,'祝日一覧'!$A:$B,2,false),"")
C86: =DAY('日付'!$E$2-WEEKDAY('日付'!$E$2,2)+18) -> 13 | L86: =DAY('日付'!$E$2-WEEKDAY('日付'!$E$2,2)+19) -> 14 | U86: =DAY('日付'!$E$2-WEEKDAY('日付'!$E$2,2)+20) -> 15 | AD86: =DAY('日付'!$E$2-WEEKDAY('日付'!$E$2,2)+21) -> 16
K94: =IFERROR(VLOOKUP('日付'!$E$2-WEEKDAY('日付'!$E$2,2)+18,'祝日一覧'!$A:$B,2,false),"") | T94: =IFERROR(VLOOKUP('日付'!$E$2-WEEKDAY('日付'!$E$2,2)+19,'祝日一覧'!$A:$B,2,false),"") | AC94: =IFERROR(VLOOKUP('日付'!$E$2-WEEKDAY('日付'!$E$2,2)+20,'祝日一覧'!$A:$B,2,false),"") | AL94: =IFERROR(VLOOKUP('日付'!$E$2-WEEKDAY('日付'!$E$2,2)+21,'祝日一覧'!$A:$B,2,false),"")
C95: =DAY('日付'!$E$2-WEEKDAY('日付'!$E$2,2)+25) -> 20 | L95: =DAY('日付'!$E$2-WEEKDAY('日付'!$E$2,2)+26) -> 21 | U95: =DAY('日付'!$E$2-WEEKDAY('日付'!$E$2,2)+27) -> 22 | AD95: =DAY('日付'!$E$2-WEEKDAY('日付'!$E$2,2)+28) -> 23
K103: =IFERROR(VLOOKUP('日付'!$E$2-WEEKDAY('日付'!$E$2,2)+25,'祝日一覧'!$A:$B,2,false),"") | T103: =IFERROR(VLOOKUP('日付'!$E$2-WEEKDAY('日付'!$E$2,2)+26,'祝日一覧'!$A:$B,2,false),"") | AC103: =IFERROR(VLOOKUP('日付'!$E$2-WEEKDAY('日付'!$E$2,2)+27,'祝日一覧'!$A:$B,2,false),"") | AL103: =IFERROR(VLOOKUP('日付'!$E$2-WEEKDAY('日付'!$E$2,2)+28,'祝日一覧'!$A:$B,2,false),"")
C104: =DAY('日付'!$E$2-WEEKDAY('日付'!$E$2,2)+32) -> 27 | L104: =DAY('日付'!$E$2-WEEKDAY('日付'!$E$2,2)+33) -> 28 | U104: =DAY('日付'!$E$2-WEEKDAY('日付'!$E$2,2)+34) -> 29 | AD104: =DAY('日付'!$E$2-WEEKDAY('日付'!$E$2,2)+35) -> 30
K112: =IFERROR(VLOOKUP('日付'!$E$2-WEEKDAY('日付'!$E$2,2)+32,'祝日一覧'!$A:$B,2,false),"") | T112: =IFERROR(VLOOKUP('日付'!$E$2-WEEKDAY('日付'!$E$2,2)+33,'祝日一覧'!$A:$B,2,false),"") | AC112: =IFERROR(VLOOKUP('日付'!$E$2-WEEKDAY('日付'!$E$2,2)+34,'祝日一覧'!$A:$B,2,false),"") | AL112: =IFERROR(VLOOKUP('日付'!$E$2-WEEKDAY('日付'!$E$2,2)+35,'祝日一覧'!$A:$B,2,false),"")
M114: =MONTH('日付'!$D$2) -> 4 | V114: =MONTH('日付'!$E$2) -> 5 | AE114: =MONTH('日付'!$F$2) -> 6
M116: =IF(DAY('日付'!$D$2-WEEKDAY('日付'!$D$2,2)+1)<=7,DAY('日付'!$D$2-WEEKDAY('日付'!$D$2,2)+1),"") | N116: =IF(DAY('日付'!$D$2-WEEKDAY('日付'!$D$2,2)+2)<=7,DAY('日付'!$D$2-WEEKDAY('日付'!$D$2,2)+2),"") | O116: =IF(DAY('日付'!$D$2-WEEKDAY('日付'!$D$2,2)+3)<=7,DAY('日付'!$D$2-WEEKDAY('日付'!$D$2,2)+3),"") | P116: =IF(DAY('日付'!$D$2-WEEKDAY('日付'!$D$2,2)+4)<=7,DAY('日付'!$D$2-WEEKDAY('日付'!$D$2,2)+4),"") -> 1 | Q116: =IF(DAY('日付'!$D$2-WEEKDAY('日付'!$D$2,2)+5)<=7,DAY('日付'!$D$2-WEEKDAY('日付'!$D$2,2)+5),"") -> 2 | R116: =IF(DAY('日付'!$D$2-WEEKDAY('日付'!$D$2,2)+6)<=7,DAY('日付'!$D$2-WEEKDAY('日付'!$D$2,2)+6),"") -> 3 | S116: =IF(DAY('日付'!$D$2-WEEKDAY('日付'!$D$2,2)+7)<=7,DAY('日付'!$D$2-WEEKDAY('日付'!$D$2,2)+7),"") -> 4 | V116: =IF(DAY('日付'!$E$2-WEEKDAY('日付'!$E$2,2)+1)<=7,DAY('日付'!$E$2-WEEKDAY('日付'!$E$2,2)+1),"") | W116: =IF(DAY('日付'!$E$2-WEEKDAY('日付'!$E$2,2)+2)<=7,DAY('日付'!$E$2-WEEKDAY('日付'!$E$2,2)+2),"") | X116: =IF(DAY('日付'!$E$2-WEEKDAY('日付'!$E$2,2)+3)<=7,DAY('日付'!$E$2-WEEKDAY('日付'!$E$2,2)+3),"") | Y116: =IF(DAY('日付'!$E$2-WEEKDAY('日付'!$E$2,2)+4)<=7,DAY('日付'!$E$2-WEEKDAY('日付'!$E$2,2)+4),"") | Z116: =IF(DAY('日付'!$E$2-WEEKDAY('日付'!$E$2,2)+5)<=7,DAY('日付'!$E$2-WEEKDAY('日付'!$E$2,2)+5),"") | AA116: =IF(DAY('日付'!$E$2-WEEKDAY('日付'!$E$2,2)+6)<=7,DAY('日付'!$E$2-WEEKDAY('日付'!$E$2,2)+6),"") -> 1 | AB116: =IF(DAY('日付'!$E$2-WEEKDAY('日付'!$E$2,2)+7)<=7,DAY('日付'!$E$2-WEEKDAY('日付'!$E$2,2)+7),"") -> 2 | AE116: =IF(DAY('日付'!$F$2-WEEKDAY('日付'!$F$2,2)+1)<=7,DAY('日付'!$F$2-WEEKDAY('日付'!$F$2,2)+1),"") | AF116: =IF(DAY('日付'!$F$2-WEEKDAY('日付'!$F$2,2)+2)<=7,DAY('日付'!$F$2-WEEKDAY('日付'!$F$2,2)+2),"") -> 1 | AG116: =IF(DAY('日付'!$F$2-WEEKDAY('日付'!$F$2,2)+3)<=7,DAY('日付'!$F$2-WEEKDAY('日付'!$F$2,2)+3),"") -> 2 | AH116: =IF(DAY('日付'!$F$2-WEEKDAY('日付'!$F$2,2)+4)<=7,DAY('日付'!$F$2-WEEKDAY('日付'!$F$2,2)+4),"") -> 3 | AI116: =IF(DAY('日付'!$F$2-WEEKDAY('日付'!$F$2,2)+5)<=7,DAY('日付'!$F$2-WEEKDAY('日付'!$F$2,2)+5),"") -> 4 | AJ116: =IF(DAY('日付'!$F$2-WEEKDAY('日付'!$F$2,2)+6)<=7,DAY('日付'!$F$2-WEEKDAY('日付'!$F$2,2)+6),"") -> 5 | AK116: =IF(DAY('日付'!$F$2-WEEKDAY('日付'!$F$2,2)+7)<=7,DAY('日付'!$F$2-WEEKDAY('日付'!$F$2,2)+7),"") -> 6
M117: =DAY('日付'!$D$2-WEEKDAY('日付'!$D$2,2)+8) -> 5 | N117: =DAY('日付'!$D$2-WEEKDAY('日付'!$D$2,2)+9) -> 6 | O117: =DAY('日付'!$D$2-WEEKDAY('日付'!$D$2,2)+10) -> 7 | P117: =DAY('日付'!$D$2-WEEKDAY('日付'!$D$2,2)+11) -> 8 | Q117: =DAY('日付'!$D$2-WEEKDAY('日付'!$D$2,2)+12) -> 9 | R117: =DAY('日付'!$D$2-WEEKDAY('日付'!$D$2,2)+13) -> 10 | S117: =DAY('日付'!$D$2-WEEKDAY('日付'!$D$2,2)+14) -> 11 | V117: =DAY('日付'!$E$2-WEEKDAY('日付'!$E$2,2)+8) -> 3 | W117: =DAY('日付'!$E$2-WEEKDAY('日付'!$E$2,2)+9) -> 4 | X117: =DAY('日付'!$E$2-WEEKDAY('日付'!$E$2,2)+10) -> 5 | Y117: =DAY('日付'!$E$2-WEEKDAY('日付'!$E$2,2)+11) -> 6 | Z117: =DAY('日付'!$E$2-WEEKDAY('日付'!$E$2,2)+12) -> 7 | AA117: =DAY('日付'!$E$2-WEEKDAY('日付'!$E$2,2)+13) -> 8 | AB117: =DAY('日付'!$E$2-WEEKDAY('日付'!$E$2,2)+14) -> 9 | AE117: =DAY('日付'!$F$2-WEEKDAY('日付'!$F$2,2)+8) -> 7 | AF117: =DAY('日付'!$F$2-WEEKDAY('日付'!$F$2,2)+9) -> 8 | AG117: =DAY('日付'!$F$2-WEEKDAY('日付'!$F$2,2)+10) -> 9 | AH117: =DAY('日付'!$F$2-WEEKDAY('日付'!$F$2,2)+11) -> 10 | AI117: =DAY('日付'!$F$2-WEEKDAY('日付'!$F$2,2)+12) -> 11 | AJ117: =DAY('日付'!$F$2-WEEKDAY('日付'!$F$2,2)+13) -> 12 | AK117: =DAY('日付'!$F$2-WEEKDAY('日付'!$F$2,2)+14) -> 13
M118: =DAY('日付'!$D$2-WEEKDAY('日付'!$D$2,2)+15) -> 12 | N118: =DAY('日付'!$D$2-WEEKDAY('日付'!$D$2,2)+16) -> 13 | O118: =DAY('日付'!$D$2-WEEKDAY('日付'!$D$2,2)+17) -> 14 | P118: =DAY('日付'!$D$2-WEEKDAY('日付'!$D$2,2)+18) -> 15 | Q118: =DAY('日付'!$D$2-WEEKDAY('日付'!$D$2,2)+19) -> 16 | R118: =DAY('日付'!$D$2-WEEKDAY('日付'!$D$2,2)+20) -> 17 | S118: =DAY('日付'!$D$2-WEEKDAY('日付'!$D$2,2)+21) -> 18 | V118: =DAY('日付'!$E$2-WEEKDAY('日付'!$E$2,2)+15) -> 10 | W118: =DAY('日付'!$E$2-WEEKDAY('日付'!$E$2,2)+16) -> 11 | X118: =DAY('日付'!$E$2-WEEKDAY('日付'!$E$2,2)+17) -> 12 | Y118: =DAY('日付'!$E$2-WEEKDAY('日付'!$E$2,2)+18) -> 13 | Z118: =DAY('日付'!$E$2-WEEKDAY('日付'!$E$2,2)+19) -> 14 | AA118: =DAY('日付'!$E$2-WEEKDAY('日付'!$E$2,2)+20) -> 15 | AB118: =DAY('日付'!$E$2-WEEKDAY('日付'!$E$2,2)+21) -> 16 | AE118: =DAY('日付'!$F$2-WEEKDAY('日付'!$F$2,2)+15) -> 14 | AF118: =DAY('日付'!$F$2-WEEKDAY('日付'!$F$2,2)+16) -> 15 | AG118: =DAY('日付'!$F$2-WEEKDAY('日付'!$F$2,2)+17) -> 16 | AH118: =DAY('日付'!$F$2-WEEKDAY('日付'!$F$2,2)+18) -> 17 | AI118: =DAY('日付'!$F$2-WEEKDAY('日付'!$F$2,2)+19) -> 18 | AJ118: =DAY('日付'!$F$2-WEEKDAY('日付'!$F$2,2)+20) -> 19 | AK118: =DAY('日付'!$F$2-WEEKDAY('日付'!$F$2,2)+21) -> 20
M119: =DAY('日付'!$D$2-WEEKDAY('日付'!$D$2,2)+22) -> 19 | N119: =DAY('日付'!$D$2-WEEKDAY('日付'!$D$2,2)+23) -> 20 | O119: =DAY('日付'!$D$2-WEEKDAY('日付'!$D$2,2)+24) -> 21 | P119: =DAY('日付'!$D$2-WEEKDAY('日付'!$D$2,2)+25) -> 22 | Q119: =DAY('日付'!$D$2-WEEKDAY('日付'!$D$2,2)+26) -> 23 | R119: =DAY('日付'!$D$2-WEEKDAY('日付'!$D$2,2)+27) -> 24 | S119: =DAY('日付'!$D$2-WEEKDAY('日付'!$D$2,2)+28) -> 25 | V119: =DAY('日付'!$E$2-WEEKDAY('日付'!$E$2,2)+22) -> 17 | W119: =DAY('日付'!$E$2-WEEKDAY('日付'!$E$2,2)+23) -> 18 | X119: =DAY('日付'!$E$2-WEEKDAY('日付'!$E$2,2)+24) -> 19 | Y119: =DAY('日付'!$E$2-WEEKDAY('日付'!$E$2,2)+25) -> 20 | Z119: =DAY('日付'!$E$2-WEEKDAY('日付'!$E$2,2)+26) -> 21 | AA119: =DAY('日付'!$E$2-WEEKDAY('日付'!$E$2,2)+27) -> 22 | AB119: =DAY('日付'!$E$2-WEEKDAY('日付'!$E$2,2)+28) -> 23 | AE119: =DAY('日付'!$F$2-WEEKDAY('日付'!$F$2,2)+22) -> 21 | AF119: =DAY('日付'!$F$2-WEEKDAY('日付'!$F$2,2)+23) -> 22 | AG119: =DAY('日付'!$F$2-WEEKDAY('日付'!$F$2,2)+24) -> 23 | AH119: =DAY('日付'!$F$2-WEEKDAY('日付'!$F$2,2)+25) -> 24 | AI119: =DAY('日付'!$F$2-WEEKDAY('日付'!$F$2,2)+26) -> 25 | AJ119: =DAY('日付'!$F$2-WEEKDAY('日付'!$F$2,2)+27) -> 26 | AK119: =DAY('日付'!$F$2-WEEKDAY('日付'!$F$2,2)+28) -> 27
M120: =IF(DAY('日付'!$D$2-WEEKDAY('日付'!$D$2,2)+29)>7,DAY('日付'!$D$2-WEEKDAY('日付'!$D$2,2)+29),"") -> 26 | N120: =IF(DAY('日付'!$D$2-WEEKDAY('日付'!$D$2,2)+30)>7,DAY('日付'!$D$2-WEEKDAY('日付'!$D$2,2)+30),"") -> 27 | O120: =IF(DAY('日付'!$D$2-WEEKDAY('日付'!$D$2,2)+31)>7,DAY('日付'!$D$2-WEEKDAY('日付'!$D$2,2)+31),"") -> 28 | P120: =IF(DAY('日付'!$D$2-WEEKDAY('日付'!$D$2,2)+32)>7,DAY('日付'!$D$2-WEEKDAY('日付'!$D$2,2)+32),"") -> 29 | Q120: =IF(DAY('日付'!$D$2-WEEKDAY('日付'!$D$2,2)+33)>7,DAY('日付'!$D$2-WEEKDAY('日付'!$D$2,2)+33),"") -> 30 | R120: =IF(DAY('日付'!$D$2-WEEKDAY('日付'!$D$2,2)+34)>7,DAY('日付'!$D$2-WEEKDAY('日付'!$D$2,2)+34),"") | S120: =IF(DAY('日付'!$D$2-WEEKDAY('日付'!$D$2,2)+35)>7,DAY('日付'!$D$2-WEEKDAY('日付'!$D$2,2)+35),"") | V120: =IF(DAY('日付'!$E$2-WEEKDAY('日付'!$E$2,2)+29)>7,DAY('日付'!$E$2-WEEKDAY('日付'!$E$2,2)+29),"") -> 24 | W120: =IF(DAY('日付'!$E$2-WEEKDAY('日付'!$E$2,2)+30)>7,DAY('日付'!$E$2-WEEKDAY('日付'!$E$2,2)+30),"") -> 25 | X120: =IF(DAY('日付'!$E$2-WEEKDAY('日付'!$E$2,2)+31)>7,DAY('日付'!$E$2-WEEKDAY('日付'!$E$2,2)+31),"") -> 26 | Y120: =IF(DAY('日付'!$E$2-WEEKDAY('日付'!$E$2,2)+32)>7,DAY('日付'!$E$2-WEEKDAY('日付'!$E$2,2)+32),"") -> 27 | Z120: =IF(DAY('日付'!$E$2-WEEKDAY('日付'!$E$2,2)+33)>7,DAY('日付'!$E$2-WEEKDAY('日付'!$E$2,2)+33),"") -> 28 | AA120: =IF(DAY('日付'!$E$2-WEEKDAY('日付'!$E$2,2)+34)>7,DAY('日付'!$E$2-WEEKDAY('日付'!$E$2,2)+34),"") -> 29 | AB120: =IF(DAY('日付'!$E$2-WEEKDAY('日付'!$E$2,2)+35)>7,DAY('日付'!$E$2-WEEKDAY('日付'!$E$2,2)+35),"") -> 30 | AE120: =IF(DAY('日付'!$F$2-WEEKDAY('日付'!$F$2,2)+29)>7,DAY('日付'!$F$2-WEEKDAY('日付'!$F$2,2)+29),"") -> 28 | AF120: =IF(DAY('日付'!$F$2-WEEKDAY('日付'!$F$2,2)+30)>7,DAY('日付'!$F$2-WEEKDAY('日付'!$F$2,2)+30),"") -> 29 | AG120: =IF(DAY('日付'!$F$2-WEEKDAY('日付'!$F$2,2)+31)>7,DAY('日付'!$F$2-WEEKDAY('日付'!$F$2,2)+31),"") -> 30 | AH120: =IF(DAY('日付'!$F$2-WEEKDAY('日付'!$F$2,2)+32)>7,DAY('日付'!$F$2-WEEKDAY('日付'!$F$2,2)+32),"") | AI120: =IF(DAY('日付'!$F$2-WEEKDAY('日付'!$F$2,2)+33)>7,DAY('日付'!$F$2-WEEKDAY('日付'!$F$2,2)+33),"") | AJ120: =IF(DAY('日付'!$F$2-WEEKDAY('日付'!$F$2,2)+34)>7,DAY('日付'!$F$2-WEEKDAY('日付'!$F$2,2)+34),"") | AK120: =IF(DAY('日付'!$F$2-WEEKDAY('日付'!$F$2,2)+35)>7,DAY('日付'!$F$2-WEEKDAY('日付'!$F$2,2)+35),"")
K121: =IFERROR(VLOOKUP('日付'!$E$2-WEEKDAY('日付'!$E$2,2)+39,'祝日一覧'!$A:$B,2,false),"") | M121: =IF(DAY('日付'!$D$2-WEEKDAY('日付'!$D$2,2)+36)>14,DAY('日付'!$D$2-WEEKDAY('日付'!$D$2,2)+36),"") | N121: =IF(DAY('日付'!$D$2-WEEKDAY('日付'!$D$2,2)+37)>14,DAY('日付'!$D$2-WEEKDAY('日付'!$D$2,2)+37),"") | O121: =IF(DAY('日付'!$D$2-WEEKDAY('日付'!$D$2,2)+38)>14,DAY('日付'!$D$2-WEEKDAY('日付'!$D$2,2)+38),"") | P121: =IF(DAY('日付'!$D$2-WEEKDAY('日付'!$D$2,2)+39)>14,DAY('日付'!$D$2-WEEKDAY('日付'!$D$2,2)+39),"") | Q121: =IF(DAY('日付'!$D$2-WEEKDAY('日付'!$D$2,2)+40)>14,DAY('日付'!$D$2-WEEKDAY('日付'!$D$2,2)+40),"") | R121: =IF(DAY('日付'!$D$2-WEEKDAY('日付'!$D$2,2)+41)>14,DAY('日付'!$D$2-WEEKDAY('日付'!$D$2,2)+41),"") | S121: =IF(DAY('日付'!$D$2-WEEKDAY('日付'!$D$2,2)+42)>14,DAY('日付'!$D$2-WEEKDAY('日付'!$D$2,2)+42),"") | V121: =IF(DAY('日付'!$E$2-WEEKDAY('日付'!$E$2,2)+36)>14,DAY('日付'!$E$2-WEEKDAY('日付'!$E$2,2)+36),"") -> 31 | W121: =IF(DAY('日付'!$E$2-WEEKDAY('日付'!$E$2,2)+37)>14,DAY('日付'!$E$2-WEEKDAY('日付'!$E$2,2)+37),"") | X121: =IF(DAY('日付'!$E$2-WEEKDAY('日付'!$E$2,2)+38)>14,DAY('日付'!$E$2-WEEKDAY('日付'!$E$2,2)+38),"") | Y121: =IF(DAY('日付'!$E$2-WEEKDAY('日付'!$E$2,2)+39)>14,DAY('日付'!$E$2-WEEKDAY('日付'!$E$2,2)+39),"") | Z121: =IF(DAY('日付'!$E$2-WEEKDAY('日付'!$E$2,2)+40)>14,DAY('日付'!$E$2-WEEKDAY('日付'!$E$2,2)+40),"") | AA121: =IF(DAY('日付'!$E$2-WEEKDAY('日付'!$E$2,2)+41)>14,DAY('日付'!$E$2-WEEKDAY('日付'!$E$2,2)+41),"") | AB121: =IF(DAY('日付'!$E$2-WEEKDAY('日付'!$E$2,2)+42)>14,DAY('日付'!$E$2-WEEKDAY('日付'!$E$2,2)+42),"") | AE121: =IF(DAY('日付'!$F$2-WEEKDAY('日付'!$F$2,2)+36)>14,DAY('日付'!$F$2-WEEKDAY('日付'!$F$2,2)+36),"") | AF121: =IF(DAY('日付'!$F$2-WEEKDAY('日付'!$F$2,2)+37)>14,DAY('日付'!$F$2-WEEKDAY('日付'!$F$2,2)+37),"") | AG121: =IF(DAY('日付'!$F$2-WEEKDAY('日付'!$F$2,2)+38)>14,DAY('日付'!$F$2-WEEKDAY('日付'!$F$2,2)+38),"") | AH121: =IF(DAY('日付'!$F$2-WEEKDAY('日付'!$F$2,2)+39)>14,DAY('日付'!$F$2-WEEKDAY('日付'!$F$2,2)+39),"") | AI121: =IF(DAY('日付'!$F$2-WEEKDAY('日付'!$F$2,2)+40)>14,DAY('日付'!$F$2-WEEKDAY('日付'!$F$2,2)+40),"") | AJ121: =IF(DAY('日付'!$F$2-WEEKDAY('日付'!$F$2,2)+41)>14,DAY('日付'!$F$2-WEEKDAY('日付'!$F$2,2)+41),"") | AK121: =IF(DAY('日付'!$F$2-WEEKDAY('日付'!$F$2,2)+42)>14,DAY('日付'!$F$2-WEEKDAY('日付'!$F$2,2)+42),"")
C123: □ | L123: □ | U123: □ | AD123: □
C125: □ | L125: □ | U125: □ | AD125: □
C128: =YEAR('日付'!A1) -> 2021 | L128: MON | U128: TUE | AD128: WED
B130: =MONTH('日付'!A1) -> 5 | K130: =DAY('日付'!$E$2-WEEKDAY('日付'!$E$2,2)+1) -> 26 | T130: =DAY('日付'!$E$2-WEEKDAY('日付'!$E$2,2)+2) -> 27 | AC130: =DAY('日付'!$E$2-WEEKDAY('日付'!$E$2,2)+3) -> 28
C131: =MONTH('日付'!A1) -> 5
C136: =TEXT('日付'!A1,"mmm") -> May
S138: =IFERROR(VLOOKUP('日付'!$E$2-WEEKDAY('日付'!$E$2,2)+1,'祝日一覧'!$A:$B,2,false),"") | AB138: =IFERROR(VLOOKUP('日付'!$E$2-WEEKDAY('日付'!$E$2,2)+2,'祝日一覧'!$A:$B,2,false),"") | AK138: =IFERROR(VLOOKUP('日付'!$E$2-WEEKDAY('日付'!$E$2,2)+3,'祝日一覧'!$A:$B,2,false),"")
...

Sheet Weekly(H)_20210408バックアップ
B2: 週間目標 | F2: =YEAR('日付'!A$1+(7-WEEKDAY('日付'!A$1,2)+1))&"年 "&MONTH('日付'!A$1+(7-WEEKDAY('日付'!A$1,2)+1))&"月 第"&WEEKNUM(YEAR('日付'!A$1+(7-WEEKDAY('日付'!A$1,2)+1))&"/"&MONTH('日付'!A$1+(7-WEEKDAY('日付'!A$1,2)+1))&"/"&DAY('日付'!A$1+(7-WEEKDAY('日付'!A$1,2)+1)),2)-WEEKNUM(YEAR('日付'!A$1+(7-WEEKDAY('日付'!A$1,2)+1))&"/"&MONTH('日付'!A$1+(7-WEEKDAY('日付'!A$1,2)+1))&"/1",1)+1&"週(第"&WEEKNUM(YEAR('日付'!A$1+(7-WEEKDAY('日付'!A$1,2)+1))&"/"&MONTH('日付'!A$1+(7-WEEKDAY('日付'!A$1,2)+1))&"/"&DAY('日付'!A$1+(7-WEEKDAY('日付'!A$1,2)+1)),2)&"週)" -> 2021年 5月 第4週(第21週)
F4: 今月のテーマ
B8: ルーティーン行動 | AF8: 月 | AG8: 火 | AH8: 水 | AI8: 木 | AJ8: 金 | AK8: 土 | AL8: 日
B9: 1
B10: 2
B11: 3
B12: 4
B13: 5
B14: 6
B16: 役割と重点タスク
B17: 役割1：自分自身
B18: 目標1：身体 | U18: 目標2：社会・情緒
B21: 目標3：知性 | U21: 目標4：精神
B25: 役割2：トレーダー
B26: 目標1： | U26: 目標2：
B29: 目標3： | U29: 目標4：
B33: 役割3：
B34: 目標1： | U34: 目標2：
B37: 目標3： | U37: 目標4：
B41: 役割4：
B42: 目標1： | U42: 目標2：
B45: 目標3： | U45: 目標4：
B49: 今週の振り返り
B50: 良かったこと | U50: 課題・改善
AG62: 利損：
C67: =MONTH('日付'!$D$2) -> 4 | E67: =IF(DAY('日付'!$D$2-WEEKDAY('日付'!$D$2,2)+1)<=7,DAY('日付'!$D$2-WEEKDAY('日付'!$D$2,2)+1),"") | F67: =IF(DAY('日付'!$D$2-WEEKDAY('日付'!$D$2,2)+2)<=7,DAY('日付'!$D$2-WEEKDAY('日付'!$D$2,2)+2),"") | G67: =IF(DAY('日付'!$D$2-WEEKDAY('日付'!$D$2,2)+3)<=7,DAY('日付'!$D$2-WEEKDAY('日付'!$D$2,2)+3),"") | H67: =IF(DAY('日付'!$D$2-WEEKDAY('日付'!$D$2,2)+4)<=7,DAY('日付'!$D$2-WEEKDAY('日付'!$D$2,2)+4),"") -> 1 | I67: =IF(DAY('日付'!$D$2-WEEKDAY('日付'!$D$2,2)+5)<=7,DAY('日付'!$D$2-WEEKDAY('日付'!$D$2,2)+5),"") -> 2 | J67: =IF(DAY('日付'!$D$2-WEEKDAY('日付'!$D$2,2)+6)<=7,DAY('日付'!$D$2-WEEKDAY('日付'!$D$2,2)+6),"") -> 3 | K67: =IF(DAY('日付'!$D$2-WEEKDAY('日付'!$D$2,2)+7)<=7,DAY('日付'!$D$2-WEEKDAY('日付'!$D$2,2)+7),"") -> 4 | O67: =MONTH('日付'!$E$2) -> 5 | Q67: =IF(DAY('日付'!$E$2-WEEKDAY('日付'!$E$2,2)+1)<=7,DAY('日付'!$E$2-WEEKDAY('日付'!$E$2,2)+1),"") | R67: =IF(DAY('日付'!$E$2-WEEKDAY('日付'!$E$2,2)+2)<=7,DAY('日付'!$E$2-WEEKDAY('日付'!$E$2,2)+2),"") | S67: =IF(DAY('日付'!$E$2-WEEKDAY('日付'!$E$2,2)+3)<=7,DAY('日付'!$E$2-WEEKDAY('日付'!$E$2,2)+3),"") | T67: =IF(DAY('日付'!$E$2-WEEKDAY('日付'!$E$2,2)+4)<=7,DAY('日付'!$E$2-WEEKDAY('日付'!$E$2,2)+4),"") | U67: =IF(DAY('日付'!$E$2-WEEKDAY('日付'!$E$2,2)+5)<=7,DAY('日付'!$E$2-WEEKDAY('日付'!$E$2,2)+5),"") | V67: =IF(DAY('日付'!$E$2-WEEKDAY('日付'!$E$2,2)+6)<=7,DAY('日付'!$E$2-WEEKDAY('日付'!$E$2,2)+6),"") -> 1 | W67: =IF(DAY('日付'!$E$2-WEEKDAY('日付'!$E$2,2)+7)<=7,DAY('日付'!$E$2-WEEKDAY('日付'!$E$2,2)+7),"") -> 2 | AB67: =MONTH('日付'!$F$2) -> 6 | AD67: =IF(DAY('日付'!$F$2-WEEKDAY('日付'!$F$2,2)+1)<=7,DAY('日付'!$F$2-WEEKDAY('日付'!$F$2,2)+1),"") | AE67: =IF(DAY('日付'!$F$2-WEEKDAY('日付'!$F$2,2)+2)<=7,DAY('日付'!$F$2-WEEKDAY('日付'!$F$2,2)+2),"") -> 1 | AF67: =IF(DAY('日付'!$F$2-WEEKDAY('日付'!$F$2,2)+3)<=7,DAY('日付'!$F$2-WEEKDAY('日付'!$F$2,2)+3),"") -> 2 | AG67: =IF(DAY('日付'!$F$2-WEEKDAY('日付'!$F$2,2)+4)<=7,DAY('日付'!$F$2-WEEKDAY('日付'!$F$2,2)+4),"") -> 3 | AH67: =IF(DAY('日付'!$F$2-WEEKDAY('日付'!$F$2,2)+5)<=7,DAY('日付'!$F$2-WEEKDAY('日付'!$F$2,2)+5),"") -> 4 | AI67: =IF(DAY('日付'!$F$2-WEEKDAY('日付'!$F$2,2)+6)<=7,DAY('日付'!$F$2-WEEKDAY('日付'!$F$2,2)+6),"") -> 5 | AJ67: =IF(DAY('日付'!$F$2-WEEKDAY('日付'!$F$2,2)+7)<=7,DAY('日付'!$F$2-WEEKDAY('日付'!$F$2,2)+7),"") -> 6
E68: =DAY('日付'!$D$2-WEEKDAY('日付'!$D$2,2)+8) -> 5 | F68: =DAY('日付'!$D$2-WEEKDAY('日付'!$D$2,2)+9) -> 6 | G68: =DAY('日付'!$D$2-WEEKDAY('日付'!$D$2,2)+10) -> 7 | H68: =DAY('日付'!$D$2-WEEKDAY('日付'!$D$2,2)+11) -> 8 | I68: =DAY('日付'!$D$2-WEEKDAY('日付'!$D$2,2)+12) -> 9 | J68: =DAY('日付'!$D$2-WEEKDAY('日付'!$D$2,2)+13) -> 10 | K68: =DAY('日付'!$D$2-WEEKDAY('日付'!$D$2,2)+14) -> 11 | Q68: =DAY('日付'!$E$2-WEEKDAY('日付'!$E$2,2)+8) -> 3 | R68: =DAY('日付'!$E$2-WEEKDAY('日付'!$E$2,2)+9) -> 4 | S68: =DAY('日付'!$E$2-WEEKDAY('日付'!$E$2,2)+10) -> 5 | T68: =DAY('日付'!$E$2-WEEKDAY('日付'!$E$2,2)+11) -> 6 | U68: =DAY('日付'!$E$2-WEEKDAY('日付'!$E$2,2)+12) -> 7 | V68: =DAY('日付'!$E$2-WEEKDAY('日付'!$E$2,2)+13) -> 8 | W68: =DAY('日付'!$E$2-WEEKDAY('日付'!$E$2,2)+14) -> 9 | AD68: =DAY('日付'!$F$2-WEEKDAY('日付'!$F$2,2)+8) -> 7 | AE68: =DAY('日付'!$F$2-WEEKDAY('日付'!$F$2,2)+9) -> 8 | AF68: =DAY('日付'!$F$2-WEEKDAY('日付'!$F$2,2)+10) -> 9 | AG68: =DAY('日付'!$F$2-WEEKDAY('日付'!$F$2,2)+11) -> 10 | AH68: =DAY('日付'!$F$2-WEEKDAY('日付'!$F$2,2)+12) -> 11 | AI68: =DAY('日付'!$F$2-WEEKDAY('日付'!$F$2,2)+13) -> 12 | AJ68: =DAY('日付'!$F$2-WEEKDAY('日付'!$F$2,2)+14) -> 13
E69: =DAY('日付'!$D$2-WEEKDAY('日付'!$D$2,2)+15) -> 12 | F69: =DAY('日付'!$D$2-WEEKDAY('日付'!$D$2,2)+16) -> 13 | G69: =DAY('日付'!$D$2-WEEKDAY('日付'!$D$2,2)+17) -> 14 | H69: =DAY('日付'!$D$2-WEEKDAY('日付'!$D$2,2)+18) -> 15 | I69: =DAY('日付'!$D$2-WEEKDAY('日付'!$D$2,2)+19) -> 16 | J69: =DAY('日付'!$D$2-WEEKDAY('日付'!$D$2,2)+20) -> 17 | K69: =DAY('日付'!$D$2-WEEKDAY('日付'!$D$2,2)+21) -> 18 | Q69: =DAY('日付'!$E$2-WEEKDAY('日付'!$E$2,2)+15) -> 10 | R69: =DAY('日付'!$E$2-WEEKDAY('日付'!$E$2,2)+16) -> 11 | S69: =DAY('日付'!$E$2-WEEKDAY('日付'!$E$2,2)+17) -> 12 | T69: =DAY('日付'!$E$2-WEEKDAY('日付'!$E$2,2)+18) -> 13 | U69: =DAY('日付'!$E$2-WEEKDAY('日付'!$E$2,2)+19) -> 14 | V69: =DAY('日付'!$E$2-WEEKDAY('日付'!$E$2,2)+20) -> 15 | W69: =DAY('日付'!$E$2-WEEKDAY('日付'!$E$2,2)+21) -> 16 | AD69: =DAY('日付'!$F$2-WEEKDAY('日付'!$F$2,2)+15) -> 14 | AE69: =DAY('日付'!$F$2-WEEKDAY('日付'!$F$2,2)+16) -> 15 | AF69: =DAY('日付'!$F$2-WEEKDAY('日付'!$F$2,2)+17) -> 16 | AG69: =DAY('日付'!$F$2-WEEKDAY('日付'!$F$2,2)+18) -> 17 | AH69: =DAY('日付'!$F$2-WEEKDAY('日付'!$F$2,2)+19) -> 18 | AI69: =DAY('日付'!$F$2-WEEKDAY('日付'!$F$2,2)+20) -> 19 | AJ69: =DAY('日付'!$F$2-WEEKDAY('日付'!$F$2,2)+21) -> 20
E70: =DAY('日付'!$D$2-WEEKDAY('日付'!$D$2,2)+22) -> 19 | F70: =DAY('日付'!$D$2-WEEKDAY('日付'!$D$2,2)+23) -> 20 | G70: =DAY('日付'!$D$2-WEEKDAY('日付'!$D$2,2)+24) -> 21 | H70: =DAY('日付'!$D$2-WEEKDAY('日付'!$D$2,2)+25) -> 22 | I70: =DAY('日付'!$D$2-WEEKDAY('日付'!$D$2,2)+26) -> 23 | J70: =DAY('日付'!$D$2-WEEKDAY('日付'!$D$2,2)+27) -> 24 | K70: =DAY('日付'!$D$2-WEEKDAY('日付'!$D$2,2)+28) -> 25 | Q70: =DAY('日付'!$E$2-WEEKDAY('日付'!$E$2,2)+22) -> 17 | R70: =DAY('日付'!$E$2-WEEKDAY('日付'!$E$2,2)+23) -> 18 | S70: =DAY('日付'!$E$2-WEEKDAY('日付'!$E$2,2)+24) -> 19 | T70: =DAY('日付'!$E$2-WEEKDAY('日付'!$E$2,2)+25) -> 20 | U70: =DAY('日付'!$E$2-WEEKDAY('日付'!$E$2,2)+26) -> 21 | V70: =DAY('日付'!$E$2-WEEKDAY('日付'!$E$2,2)+27) -> 22 | W70: =DAY('日付'!$E$2-WEEKDAY('日付'!$E$2,2)+28) -> 23 | AD70: =DAY('日付'!$F$2-WEEKDAY('日付'!$F$2,2)+22) -> 21 | AE70: =DAY('日付'!$F$2-WEEKDAY('日付'!$F$2,2)+23) -> 22 | AF70: =DAY('日付'!$F$2-WEEKDAY('日付'!$F$2,2)+24) -> 23 | AG70: =DAY('日付'!$F$2-WEEKDAY('日付'!$F$2,2)+25) -> 24 | AH70: =DAY('日付'!$F$2-WEEKDAY('日付'!$F$2,2)+26) -> 25 | AI70: =DAY('日付'!$F$2-WEEKDAY('日付'!$F$2,2)+27) -> 26 | AJ70: =DAY('日付'!$F$2-WEEKDAY('日付'!$F$2,2)+28) -> 27
E71: =IF(DAY('日付'!$D$2-WEEKDAY('日付'!$D$2,2)+29)>7,DAY('日付'!$D$2-WEEKDAY('日付'!$D$2,2)+29),"") -> 26 | F71: =IF(DAY('日付'!$D$2-WEEKDAY('日付'!$D$2,2)+30)>7,DAY('日付'!$D$2-WEEKDAY('日付'!$D$2,2)+30),"") -> 27 | G71: =IF(DAY('日付'!$D$2-WEEKDAY('日付'!$D$2,2)+31)>7,DAY('日付'!$D$2-WEEKDAY('日付'!$D$2,2)+31),"") -> 28 | H71: =IF(DAY('日付'!$D$2-WEEKDAY('日付'!$D$2,2)+32)>7,DAY('日付'!$D$2-WEEKDAY('日付'!$D$2,2)+32),"") -> 29 | I71: =IF(DAY('日付'!$D$2-WEEKDAY('日付'!$D$2,2)+33)>7,DAY('日付'!$D$2-WEEKDAY('日付'!$D$2,2)+33),"") -> 30 | J71: =IF(DAY('日付'!$D$2-WEEKDAY('日付'!$D$2,2)+34)>7,DAY('日付'!$D$2-WEEKDAY('日付'!$D$2,2)+34),"") | K71: =IF(DAY('日付'!$D$2-WEEKDAY('日付'!$D$2,2)+35)>7,DAY('日付'!$D$2-WEEKDAY('日付'!$D$2,2)+35),"") | Q71: =IF(DAY('日付'!$E$2-WEEKDAY('日付'!$E$2,2)+29)>7,DAY('日付'!$E$2-WEEKDAY('日付'!$E$2,2)+29),"") -> 24 | R71: =IF(DAY('日付'!$E$2-WEEKDAY('日付'!$E$2,2)+30)>7,DAY('日付'!$E$2-WEEKDAY('日付'!$E$2,2)+30),"") -> 25 | S71: =IF(DAY('日付'!$E$2-WEEKDAY('日付'!$E$2,2)+31)>7,DAY('日付'!$E$2-WEEKDAY('日付'!$E$2,2)+31),"") -> 26 | T71: =IF(DAY('日付'!$E$2-WEEKDAY('日付'!$E$2,2)+32)>7,DAY('日付'!$E$2-WEEKDAY('日付'!$E$2,2)+32),"") -> 27 | U71: =IF(DAY('日付'!$E$2-WEEKDAY('日付'!$E$2,2)+33)>7,DAY('日付'!$E$2-WEEKDAY('日付'!$E$2,2)+33),"") -> 28 | V71: =IF(DAY('日付'!$E$2-WEEKDAY('日付'!$E$2,2)+34)>7,DAY('日付'!$E$2-WEEKDAY('日付'!$E$2,2)+34),"") -> 29 | W71: =IF(DAY('日付'!$E$2-WEEKDAY('日付'!$E$2,2)+35)>7,DAY('日付'!$E$2-WEEKDAY('日付'!$E$2,2)+35),"") -> 30 | AD71: =IF(DAY('日付'!$F$2-WEEKDAY('日付'!$F$2,2)+29)>7,DAY('日付'!$F$2-WEEKDAY('日付'!$F$2,2)+29),"") -> 28 | AE71: =IF(DAY('日付'!$F$2-WEEKDAY('日付'!$F$2,2)+30)>7,DAY('日付'!$F$2-WEEKDAY('日付'!$F$2,2)+30),"") -> 29 | AF71: =IF(DAY('日付'!$F$2-WEEKDAY('日付'!$F$2,2)+31)>7,DAY('日付'!$F$2-WEEKDAY('日付'!$F$2,2)+31),"") -> 30 | AG71: =IF(DAY('日付'!$F$2-WEEKDAY('日付'!$F$2,2)+32)>7,DAY('日付'!$F$2-WEEKDAY('日付'!$F$2,2)+32),"") | AH71: =IF(DAY('日付'!$F$2-WEEKDAY('日付'!$F$2,2)+33)>7,DAY('日付'!$F$2-WEEKDAY('日付'!$F$2,2)+33),"") | AI71: =IF(DAY('日付'!$F$2-WEEKDAY('日付'!$F$2,2)+34)>7,DAY('日付'!$F$2-WEEKDAY('日付'!$F$2,2)+34),"") | AJ71: =IF(DAY('日付'!$F$2-WEEKDAY('日付'!$F$2,2)+35)>7,DAY('日付'!$F$2-WEEKDAY('日付'!$F$2,2)+35),"")
E72: =IF(DAY('日付'!$D$2-WEEKDAY('日付'!$D$2,2)+36)>14,DAY('日付'!$D$2-WEEKDAY('日付'!$D$2,2)+36),"") | F72: =IF(DAY('日付'!$D$2-WEEKDAY('日付'!$D$2,2)+37)>14,DAY('日付'!$D$2-WEEKDAY('日付'!$D$2,2)+37),"") | G72: =IF(DAY('日付'!$D$2-WEEKDAY('日付'!$D$2,2)+38)>14,DAY('日付'!$D$2-WEEKDAY('日付'!$D$2,2)+38),"") | H72: =IF(DAY('日付'!$D$2-WEEKDAY('日付'!$D$2,2)+39)>14,DAY('日付'!$D$2-WEEKDAY('日付'!$D$2,2)+39),"") | I72: =IF(DAY('日付'!$D$2-WEEKDAY('日付'!$D$2,2)+40)>14,DAY('日付'!$D$2-WEEKDAY('日付'!$D$2,2)+40),"") | J72: =IF(DAY('日付'!$D$2-WEEKDAY('日付'!$D$2,2)+41)>14,DAY('日付'!$D$2-WEEKDAY('日付'!$D$2,2)+41),"") | K72: =IF(DAY('日付'!$D$2-WEEKDAY('日付'!$D$2,2)+42)>14,DAY('日付'!$D$2-WEEKDAY('日付'!$D$2,2)+42),"") | Q72: =IF(DAY('日付'!$E$2-WEEKDAY('日付'!$E$2,2)+36)>14,DAY('日付'!$E$2-WEEKDAY('日付'!$E$2,2)+36),"") -> 31 | R72: =IF(DAY('日付'!$E$2-WEEKDAY('日付'!$E$2,2)+37)>14,DAY('日付'!$E$2-WEEKDAY('日付'!$E$2,2)+37),"") | S72: =IF(DAY('日付'!$E$2-WEEKDAY('日付'!$E$2,2)+38)>14,DAY('日付'!$E$2-WEEKDAY('日付'!$E$2,2)+38),"") | T72: =IF(DAY('日付'!$E$2-WEEKDAY('日付'!$E$2,2)+39)>14,DAY('日付'!$E$2-WEEKDAY('日付'!$E$2,2)+39),"") | U72: =IF(DAY('日付'!$E$2-WEEKDAY('日付'!$E$2,2)+40)>14,DAY('日付'!$E$2-WEEKDAY('日付'!$E$2,2)+40),"") | V72: =IF(DAY('日付'!$E$2-WEEKDAY('日付'!$E$2,2)+41)>14,DAY('日付'!$E$2-WEEKDAY('日付'!$E$2,2)+41),"") | W72: =IF(DAY('日付'!$E$2-WEEKDAY('日付'!$E$2,2)+42)>14,DAY('日付'!$E$2-WEEKDAY('日付'!$E$2,2)+42),"") | AD72: =IF(DAY('日付'!$F$2-WEEKDAY('日付'!$F$2,2)+36)>14,DAY('日付'!$F$2-WEEKDAY('日付'!$F$2,2)+36),"") | AE72: =IF(DAY('日付'!$F$2-WEEKDAY('日付'!$F$2,2)+37)>14,DAY('日付'!$F$2-WEEKDAY('日付'!$F$2,2)+37),"") | AF72: =IF(DAY('日付'!$F$2-WEEKDAY('日付'!$F$2,2)+38)>14,DAY('日付'!$F$2-WEEKDAY('日付'!$F$2,2)+38),"") | AG72: =IF(DAY('日付'!$F$2-WEEKDAY('日付'!$F$2,2)+39)>14,DAY('日付'!$F$2-WEEKDAY('日付'!$F$2,2)+39),"") | AH72: =IF(DAY('日付'!$F$2-WEEKDAY('日付'!$F$2,2)+40)>14,DAY('日付'!$F$2-WEEKDAY('日付'!$F$2,2)+40),"") | AI72: =IF(DAY('日付'!$F$2-WEEKDAY('日付'!$F$2,2)+41)>14,DAY('日付'!$F$2-WEEKDAY('日付'!$F$2,2)+41),"") | AJ72: =IF(DAY('日付'!$F$2-WEEKDAY('日付'!$F$2,2)+42)>14,DAY('日付'!$F$2-WEEKDAY('日付'!$F$2,2)+42),"")
B73: =MONTH('日付'!A$1+(7-WEEKDAY('日付'!A$1,2)+1)) -> 5 | D73: 月 | E73: 今日の一言：
B79: =DAY('日付'!A$1+(7-WEEKDAY('日付'!A$1,2)+1)) -> 17
AG81: 利損：
AL82: =IFERROR(VLOOKUP('日付'!A$1+(7-WEEKDAY('日付'!A$1,2)+1),'祝日一覧'!A:B,2,false),"")
B83: =MONTH('日付'!A$1+(7-WEEKDAY('日付'!A$1,2)+2)) -> 5 | D83: 火 | E83: 今日の一言：
B89: =DAY('日付'!A$1+(7-WEEKDAY('日付'!A$1,2)+2)) -> 18
AG91: 利損：
AL92: =IFERROR(VLOOKUP('日付'!A$1+(7-WEEKDAY('日付'!A$1,2)+2),'祝日一覧'!A:B,2,false),"")
B93: =MONTH('日付'!A$1+(7-WEEKDAY('日付'!A$1,2)+3)) -> 5 | D93: 水 | E93: 今日の一言：
...

Sheet Monthly_20210408バックアップ
E2: =YEAR('日付'!A1) -> 2021 | H2: 年 | J2: =MONTH('日付'!A1) -> 5 | L2: 月
A4: chk | C4: Priority | F4: プライベート | U4: chk | W4: Priority | Z4: ビジネス
A5: □ | U5: □
A7: □ | U7: □
A9: □ | U9: □
A11: □ | U11: □
A13: □ | U13: □
A15: □ | U15: □
A17: □ | U17: □
A19: □ | U19: □
A21: □ | U21: □
A23: □ | U23: □
A25: □ | U25: □
A27: □ | U27: □
... A61: □ | U61: □
C66: =YEAR('日付'!A1) -> 2021 | L66: MON | U66: TUE | AD66: WED
B68: =MONTH('日付'!A1) -> 5 | K68: =DAY('日付'!$E$2-WEEKDAY('日付'!$E$2,2)+1) -> 26 | T68: =DAY('日付'!$E$2-WEEKDAY('日付'!$E$2,2)+2) -> 27 | AC68: =DAY('日付'!$E$2-WEEKDAY('日付'!$E$2,2)+3) -> 28
C69: =MONTH('日付'!A1) -> 5
C74: =TEXT('日付'!A1,"mmm") -> May
S76: =IFERROR(VLOOKUP('日付'!$E$2-WEEKDAY('日付'!$E$2,2)+1,'祝日一覧'!$A:$B,2,false),"") | AB76: =IFERROR(VLOOKUP('日付'!$E$2-WEEKDAY('日付'!$E$2,2)+2,'祝日一覧'!$A:$B,2,false),"") | AK76: =IFERROR(VLOOKUP('日付'!$E$2-WEEKDAY('日付'!$E$2,2)+3,'祝日一覧'!$A:$B,2,false),"")
B77: □ | K77: =DAY('日付'!$E$2-WEEKDAY('日付'!$E$2,2)+8) -> 3 | T77: =DAY('日付'!$E$2-WEEKDAY('日付'!$E$2,2)+9) -> 4 | AC77: =DAY('日付'!$E$2-WEEKDAY('日付'!$E$2,2)+10) -> 5
B79: □
B81: □
B83: □
B85: □ | S85: =IFERROR(VLOOKUP('日付'!$E$2-WEEKDAY('日付'!$E$2,2)+8,'祝日一覧'!$A:$B,2,false),"") -> 憲法記念日 | AB85: =IFERROR(VLOOKUP('日付'!$E$2-WEEKDAY('日付'!$E$2,2)+9,'祝日一覧'!$A:$B,2,false),"") -> みどりの日 | AK85: =IFERROR(VLOOKUP('日付'!$E$2-WEEKDAY('日付'!$E$2,2)+10,'祝日一覧'!$A:$B,2,false),"") -> こどもの日
K86: =DAY('日付'!$E$2-WEEKDAY('日付'!$E$2,2)+15) -> 10 | T86: =DAY('日付'!$E$2-WEEKDAY('日付'!$E$2,2)+16) -> 11 | AC86: =DAY('日付'!$E$2-WEEKDAY('日付'!$E$2,2)+17) -> 12
B87: □
B89: □
B91: □
B93: □
S94: =IFERROR(VLOOKUP('日付'!$E$2-WEEKDAY('日付'!$E$2,2)+15,'祝日一覧'!$A:$B,2,false),"") | AB94: =IFERROR(VLOOKUP('日付'!$E$2-WEEKDAY('日付'!$E$2,2)+16,'祝日一覧'!$A:$B,2,false),"") | AK94: =IFERROR(VLOOKUP('日付'!$E$2-WEEKDAY('日付'!$E$2,2)+17,'祝日一覧'!$A:$B,2,false),"")
B95: □ | K95: =DAY('日付'!$E$2-WEEKDAY('日付'!$E$2,2)+22) -> 17 | T95: =DAY('日付'!$E$2-WEEKDAY('日付'!$E$2,2)+23) -> 18 | AC95: =DAY('日付'!$E$2-WEEKDAY('日付'!$E$2,2)+24) -> 19
B97: □
B99: □
B101: □
B103: □ | S103: =IFERROR(VLOOKUP('日付'!$E$2-WEEKDAY('日付'!$E$2,2)+22,'祝日一覧'!$A:$B,2,false),"") | AB103: =IFERROR(VLOOKUP('日付'!$E$2-WEEKDAY('日付'!$E$2,2)+23,'祝日一覧'!$A:$B,2,false),"") | AK103: =IFERROR(VLOOKUP('日付'!$E$2-WEEKDAY('日付'!$E$2,2)+24,'祝日一覧'!$A:$B,2,false),"")
K104: =DAY('日付'!$E$2-WEEKDAY('日付'!$E$2,2)+29) -> 24 | T104: =DAY('日付'!$E$2-WEEKDAY('日付'!$E$2,2)+30) -> 25 | AC104: =DAY('日付'!$E$2-WEEKDAY('日付'!$E$2,2)+31) -> 26
B105: □
B107: □
B109: □
...

Sheet Weekly(V)
B2: 週間目標 | F2: 今月のテーマ
B5: ルーティーン行動 | O5: 月 | P5: 火 | Q5: 水 | R5: 木 | S5: 金 | T5: 土 | U5: 日 | W5: □
B6: 1
B7: 2 | W7: □
B8: 3
B9: 4 | W9: □
B10: 5
B11: 6 | W11: □
W13: □
B15: 役割と重点タスク
B16: 役割1：
B17: 目標1：身体 | R17: 目標2：社会・情緒
B20: 目標3：知性 | R20: 目標4：精神
B24: 役割2：
B25: 目標1： | R25: 目標2：
B28: 目標3： | R28: 目標4：
B32: 役割3：
B33: 目標1： | R33: 目標2：
B36: 目標3： | R36: 目標4：
B40: 今週の振り返り
B41: 良かったこと | R41: 課題・改善
C52: =MONTH('日付'!$D$2) -> 4 | E52: =IF(DAY('日付'!$D$2-WEEKDAY('日付'!$D$2,2)+1)<=7,DAY('日付'!$D$2-WEEKDAY('日付'!$D$2,2)+1),"") | F52: =IF(DAY('日付'!$D$2-WEEKDAY('日付'!$D$2,2)+2)<=7,DAY('日付'!$D$2-WEEKDAY('日付'!$D$2,2)+2),"") | G52: =IF(DAY('日付'!$D$2-WEEKDAY('日付'!$D$2,2)+3)<=7,DAY('日付'!$D$2-WEEKDAY('日付'!$D$2,2)+3),"") | H52: =IF(DAY('日付'!$D$2-WEEKDAY('日付'!$D$2,2)+4)<=7,DAY('日付'!$D$2-WEEKDAY('日付'!$D$2,2)+4),"") -> 1 | I52: =IF(DAY('日付'!$D$2-WEEKDAY('日付'!$D$2,2)+5)<=7,DAY('日付'!$D$2-WEEKDAY('日付'!$D$2,2)+5),"") -> 2 | J52: =IF(DAY('日付'!$D$2-WEEKDAY('日付'!$D$2,2)+6)<=7,DAY('日付'!$D$2-WEEKDAY('日付'!$D$2,2)+6),"") -> 3 | K52: =IF(DAY('日付'!$D$2-WEEKDAY('日付'!$D$2,2)+7)<=7,DAY('日付'!$D$2-WEEKDAY('日付'!$D$2,2)+7),"") -> 4 | M52: =MONTH('日付'!$E$2) -> 5 | O52: =IF(DAY('日付'!$E$2-WEEKDAY('日付'!$E$2,2)+1)<=7,DAY('日付'!$E$2-WEEKDAY('日付'!$E$2,2)+1),"") | P52: =IF(DAY('日付'!$E$2-WEEKDAY('日付'!$E$2,2)+2)<=7,DAY('日付'!$E$2-WEEKDAY('日付'!$E$2,2)+2),"") | Q52: =IF(DAY('日付'!$E$2-WEEKDAY('日付'!$E$2,2)+3)<=7,DAY('日付'!$E$2-WEEKDAY('日付'!$E$2,2)+3),"") | R52: =IF(DAY('日付'!$E$2-WEEKDAY('日付'!$E$2,2)+4)<=7,DAY('日付'!$E$2-WEEKDAY('日付'!$E$2,2)+4),"") | S52: =IF(DAY('日付'!$E$2-WEEKDAY('日付'!$E$2,2)+5)<=7,DAY('日付'!$E$2-WEEKDAY('日付'!$E$2,2)+5),"") | T52: =IF(DAY('日付'!$E$2-WEEKDAY('日付'!$E$2,2)+6)<=7,DAY('日付'!$E$2-WEEKDAY('日付'!$E$2,2)+6),"") -> 1 | U52: =IF(DAY('日付'!$E$2-WEEKDAY('日付'!$E$2,2)+7)<=7,DAY('日付'!$E$2-WEEKDAY('日付'!$E$2,2)+7),"") -> 2 | W52: =MONTH('日付'!$F$2) -> 6 | Y52: =IF(DAY('日付'!$F$2-WEEKDAY('日付'!$F$2,2)+1)<=7,DAY('日付'!$F$2-WEEKDAY('日付'!$F$2,2)+1),"") | Z52: =IF(DAY('日付'!$F$2-WEEKDAY('日付'!$F$2,2)+2)<=7,DAY('日付'!$F$2-WEEKDAY('日付'!$F$2,2)+2),"") -> 1 | AA52: =IF(DAY('日付'!$F$2-WEEKDAY('日付'!$F$2,2)+3)<=7,DAY('日付'!$F$2-WEEKDAY('日付'!$F$2,2)+3),"") -> 2 | AB52: =IF(DAY('日付'!$F$2-WEEKDAY('日付'!$F$2,2)+4)<=7,DAY('日付'!$F$2-WEEKDAY('日付'!$F$2,2)+4),"") -> 3 | AC52: =IF(DAY('日付'!$F$2-WEEKDAY('日付'!$F$2,2)+5)<=7,DAY('日付'!$F$2-WEEKDAY('日付'!$F$2,2)+5),"") -> 4 | AD52: =IF(DAY('日付'!$F$2-WEEKDAY('日付'!$F$2,2)+6)<=7,DAY('日付'!$F$2-WEEKDAY('日付'!$F$2,2)+6),"") -> 5 | AE52: =IF(DAY('日付'!$F$2-WEEKDAY('日付'!$F$2,2)+7)<=7,DAY('日付'!$F$2-WEEKDAY('日付'!$F$2,2)+7),"") -> 6
E53: =DAY('日付'!$D$2-WEEKDAY('日付'!$D$2,2)+8) -> 5 | F53: =DAY('日付'!$D$2-WEEKDAY('日付'!$D$2,2)+9) -> 6 | G53: =DAY('日付'!$D$2-WEEKDAY('日付'!$D$2,2)+10) -> 7 | H53: =DAY('日付'!$D$2-WEEKDAY('日付'!$D$2,2)+11) -> 8 | I53: =DAY('日付'!$D$2-WEEKDAY('日付'!$D$2,2)+12) -> 9 | J53: =DAY('日付'!$D$2-WEEKDAY('日付'!$D$2,2)+13) -> 10 | K53: =DAY('日付'!$D$2-WEEKDAY('日付'!$D$2,2)+14) -> 11 | O53: =DAY('日付'!$E$2-WEEKDAY('日付'!$E$2,2)+8) -> 3 | P53: =DAY('日付'!$E$2-WEEKDAY('日付'!$E$2,2)+9) -> 4 | Q53: =DAY('日付'!$E$2-WEEKDAY('日付'!$E$2,2)+10) -> 5 | R53: =DAY('日付'!$E$2-WEEKDAY('日付'!$E$2,2)+11) -> 6 | S53: =DAY('日付'!$E$2-WEEKDAY('日付'!$E$2,2)+12) -> 7 | T53: =DAY('日付'!$E$2-WEEKDAY('日付'!$E$2,2)+13) -> 8 | U53: =DAY('日付'!$E$2-WEEKDAY('日付'!$E$2,2)+14) -> 9 | Y53: =DAY('日付'!$F$2-WEEKDAY('日付'!$F$2,2)+8) -> 7 | Z53: =DAY('日付'!$F$2-WEEKDAY('日付'!$F$2,2)+9) -> 8 | AA53: =DAY('日付'!$F$2-WEEKDAY('日付'!$F$2,2)+10) -> 9 | AB53: =DAY('日付'!$F$2-WEEKDAY('日付'!$F$2,2)+11) -> 10 | AC53: =DAY('日付'!$F$2-WEEKDAY('日付'!$F$2,2)+12) -> 11 | AD53: =DAY('日付'!$F$2-WEEKDAY('日付'!$F$2,2)+13) -> 12 | AE53: =DAY('日付'!$F$2-WEEKDAY('日付'!$F$2,2)+14) -> 13
E54: =DAY('日付'!$D$2-WEEKDAY('日付'!$D$2,2)+15) -> 12 | F54: =DAY('日付'!$D$2-WEEKDAY('日付'!$D$2,2)+16) -> 13 | G54: =DAY('日付'!$D$2-WEEKDAY('日付'!$D$2,2)+17) -> 14 | H54: =DAY('日付'!$D$2-WEEKDAY('日付'!$D$2,2)+18) -> 15 | I54: =DAY('日付'!$D$2-WEEKDAY('日付'!$D$2,2)+19) -> 16 | J54: =DAY('日付'!$D$2-WEEKDAY('日付'!$D$2,2)+20) -> 17 | K54: =DAY('日付'!$D$2-WEEKDAY('日付'!$D$2,2)+21) -> 18 | O54: =DAY('日付'!$E$2-WEEKDAY('日付'!$E$2,2)+15) -> 10 | P54: =DAY('日付'!$E$2-WEEKDAY('日付'!$E$2,2)+16) -> 11 | Q54: =DAY('日付'!$E$2-WEEKDAY('日付'!$E$2,2)+17) -> 12 | R54: =DAY('日付'!$E$2-WEEKDAY('日付'!$E$2,2)+18) -> 13 | S54: =DAY('日付'!$E$2-WEEKDAY('日付'!$E$2,2)+19) -> 14 | T54: =DAY('日付'!$E$2-WEEKDAY('日付'!$E$2,2)+20) -> 15 | U54: =DAY('日付'!$E$2-WEEKDAY('日付'!$E$2,2)+21) -> 16 | Y54: =DAY('日付'!$F$2-WEEKDAY('日付'!$F$2,2)+15) -> 14 | Z54: =DAY('日付'!$F$2-WEEKDAY('日付'!$F$2,2)+16) -> 15 | AA54: =DAY('日付'!$F$2-WEEKDAY('日付'!$F$2,2)+17) -> 16 | AB54: =DAY('日付'!$F$2-WEEKDAY('日付'!$F$2,2)+18) -> 17 | AC54: =DAY('日付'!$F$2-WEEKDAY('日付'!$F$2,2)+19) -> 18 | AD54: =DAY('日付'!$F$2-WEEKDAY('日付'!$F$2,2)+20) -> 19 | AE54: =DAY('日付'!$F$2-WEEKDAY('日付'!$F$2,2)+21) -> 20
E55: =DAY('日付'!$D$2-WEEKDAY('日付'!$D$2,2)+22) -> 19 | F55: =DAY('日付'!$D$2-WEEKDAY('日付'!$D$2,2)+23) -> 20 | G55: =DAY('日付'!$D$2-WEEKDAY('日付'!$D$2,2)+24) -> 21 | H55: =DAY('日付'!$D$2-WEEKDAY('日付'!$D$2,2)+25) -> 22 | I55: =DAY('日付'!$D$2-WEEKDAY('日付'!$D$2,2)+26) -> 23 | J55: =DAY('日付'!$D$2-WEEKDAY('日付'!$D$2,2)+27) -> 24 | K55: =DAY('日付'!$D$2-WEEKDAY('日付'!$D$2,2)+28) -> 25 | O55: =DAY('日付'!$E$2-WEEKDAY('日付'!$E$2,2)+22) -> 17 | P55: =DAY('日付'!$E$2-WEEKDAY('日付'!$E$2,2)+23) -> 18 | Q55: =DAY('日付'!$E$2-WEEKDAY('日付'!$E$2,2)+24) -> 19 | R55: =DAY('日付'!$E$2-WEEKDAY('日付'!$E$2,2)+25) -> 20 | S55: =DAY('日付'!$E$2-WEEKDAY('日付'!$E$2,2)+26) -> 21 | T55: =DAY('日付'!$E$2-WEEKDAY('日付'!$E$2,2)+27) -> 22 | U55: =DAY('日付'!$E$2-WEEKDAY('日付'!$E$2,2)+28) -> 23 | Y55: =DAY('日付'!$F$2-WEEKDAY('日付'!$F$2,2)+22) -> 21 | Z55: =DAY('日付'!$F$2-WEEKDAY('日付'!$F$2,2)+23) -> 22 | AA55: =DAY('日付'!$F$2-WEEKDAY('日付'!$F$2,2)+24) -> 23 | AB55: =DAY('日付'!$F$2-WEEKDAY('日付'!$F$2,2)+25) -> 24 | AC55: =DAY('日付'!$F$2-WEEKDAY('日付'!$F$2,2)+26) -> 25 | AD55: =DAY('日付'!$F$2-WEEKDAY('日付'!$F$2,2)+27) -> 26 | AE55: =DAY('日付'!$F$2-WEEKDAY('日付'!$F$2,2)+28) -> 27
E56: =IF(DAY('日付'!$D$2-WEEKDAY('日付'!$D$2,2)+29)>7,DAY('日付'!$D$2-WEEKDAY('日付'!$D$2,2)+29),"") -> 26 | F56: =IF(DAY('日付'!$D$2-WEEKDAY('日付'!$D$2,2)+30)>7,DAY('日付'!$D$2-WEEKDAY('日付'!$D$2,2)+30),"") -> 27 | G56: =IF(DAY('日付'!$D$2-WEEKDAY('日付'!$D$2,2)+31)>7,DAY('日付'!$D$2-WEEKDAY('日付'!$D$2,2)+31),"") -> 28 | H56: =IF(DAY('日付'!$D$2-WEEKDAY('日付'!$D$2,2)+32)>7,DAY('日付'!$D$2-WEEKDAY('日付'!$D$2,2)+32),"") -> 29 | I56: =IF(DAY('日付'!$D$2-WEEKDAY('日付'!$D$2,2)+33)>7,DAY('日付'!$D$2-WEEKDAY('日付'!$D$2,2)+33),"") -> 30 | J56: =IF(DAY('日付'!$D$2-WEEKDAY('日付'!$D$2,2)+34)>7,DAY('日付'!$D$2-WEEKDAY('日付'!$D$2,2)+34),"") | K56: =IF(DAY('日付'!$D$2-WEEKDAY('日付'!$D$2,2)+35)>7,DAY('日付'!$D$2-WEEKDAY('日付'!$D$2,2)+35),"") | O56: =IF(DAY('日付'!$E$2-WEEKDAY('日付'!$E$2,2)+29)>7,DAY('日付'!$E$2-WEEKDAY('日付'!$E$2,2)+29),"") -> 24 | P56: =IF(DAY('日付'!$E$2-WEEKDAY('日付'!$E$2,2)+30)>7,DAY('日付'!$E$2-WEEKDAY('日付'!$E$2,2)+30),"") -> 25 | Q56: =IF(DAY('日付'!$E$2-WEEKDAY('日付'!$E$2,2)+31)>7,DAY('日付'!$E$2-WEEKDAY('日付'!$E$2,2)+31),"") -> 26 | R56: =IF(DAY('日付'!$E$2-WEEKDAY('日付'!$E$2,2)+32)>7,DAY('日付'!$E$2-WEEKDAY('日付'!$E$2,2)+32),"") -> 27 | S56: =IF(DAY('日付'!$E$2-WEEKDAY('日付'!$E$2,2)+33)>7,DAY('日付'!$E$2-WEEKDAY('日付'!$E$2,2)+33),"") -> 28 | T56: =IF(DAY('日付'!$E$2-WEEKDAY('日付'!$E$2,2)+34)>7,DAY('日付'!$E$2-WEEKDAY('日付'!$E$2,2)+34),"") -> 29 | U56: =IF(DAY('日付'!$E$2-WEEKDAY('日付'!$E$2,2)+35)>7,DAY('日付'!$E$2-WEEKDAY('日付'!$E$2,2)+35),"") -> 30 | Y56: =IF(DAY('日付'!$F$2-WEEKDAY('日付'!$F$2,2)+29)>7,DAY('日付'!$F$2-WEEKDAY('日付'!$F$2,2)+29),"") -> 28 | Z56: =IF(DAY('日付'!$F$2-WEEKDAY('日付'!$F$2,2)+30)>7,DAY('日付'!$F$2-WEEKDAY('日付'!$F$2,2)+30),"") -> 29 | AA56: =IF(DAY('日付'!$F$2-WEEKDAY('日付'!$F$2,2)+31)>7,DAY('日付'!$F$2-WEEKDAY('日付'!$F$2,2)+31),"") -> 30 | AB56: =IF(DAY('日付'!$F$2-WEEKDAY('日付'!$F$2,2)+32)>7,DAY('日付'!$F$2-WEEKDAY('日付'!$F$2,2)+32),"") | AC56: =IF(DAY('日付'!$F$2-WEEKDAY('日付'!$F$2,2)+33)>7,DAY('日付'!$F$2-WEEKDAY('日付'!$F$2,2)+33),"") | AD56: =IF(DAY('日付'!$F$2-WEEKDAY('日付'!$F$2,2)+34)>7,DAY('日付'!$F$2-WEEKDAY('日付'!$F$2,2)+34),"") | AE56: =IF(DAY('日付'!$F$2-WEEKDAY('日付'!$F$2,2)+35)>7,DAY('日付'!$F$2-WEEKDAY('日付'!$F$2,2)+35),"")
E57: =IF(DAY('日付'!$D$2-WEEKDAY('日付'!$D$2,2)+36)>14,DAY('日付'!$D$2-WEEKDAY('日付'!$D$2,2)+36),"") | F57: =IF(DAY('日付'!$D$2-WEEKDAY('日付'!$D$2,2)+37)>14,DAY('日付'!$D$2-WEEKDAY('日付'!$D$2,2)+37),"") | G57: =IF(DAY('日付'!$D$2-WEEKDAY('日付'!$D$2,2)+38)>14,DAY('日付'!$D$2-WEEKDAY('日付'!$D$2,2)+38),"") | H57: =IF(DAY('日付'!$D$2-WEEKDAY('日付'!$D$2,2)+39)>14,DAY('日付'!$D$2-WEEKDAY('日付'!$D$2,2)+39),"") | I57: =IF(DAY('日付'!$D$2-WEEKDAY('日付'!$D$2,2)+40)>14,DAY('日付'!$D$2-WEEKDAY('日付'!$D$2,2)+40),"") | J57: =IF(DAY('日付'!$D$2-WEEKDAY('日付'!$D$2,2)+41)>14,DAY('日付'!$D$2-WEEKDAY('日付'!$D$2,2)+41),"") | K57: =IF(DAY('日付'!$D$2-WEEKDAY('日付'!$D$2,2)+42)>14,DAY('日付'!$D$2-WEEKDAY('日付'!$D$2,2)+42),"") | O57: =IF(DAY('日付'!$E$2-WEEKDAY('日付'!$E$2,2)+36)>14,DAY('日付'!$E$2-WEEKDAY('日付'!$E$2,2)+36),"") -> 31 | P57: =IF(DAY('日付'!$E$2-WEEKDAY('日付'!$E$2,2)+37)>14,DAY('日付'!$E$2-WEEKDAY('日付'!$E$2,2)+37),"") | Q57: =IF(DAY('日付'!$E$2-WEEKDAY('日付'!$E$2,2)+38)>14,DAY('日付'!$E$2-WEEKDAY('日付'!$E$2,2)+38),"") | R57: =IF(DAY('日付'!$E$2-WEEKDAY('日付'!$E$2,2)+39)>14,DAY('日付'!$E$2-WEEKDAY('日付'!$E$2,2)+39),"") | S57: =IF(DAY('日付'!$E$2-WEEKDAY('日付'!$E$2,2)+40)>14,DAY('日付'!$E$2-WEEKDAY('日付'!$E$2,2)+40),"") | T57: =IF(DAY('日付'!$E$2-WEEKDAY('日付'!$E$2,2)+41)>14,DAY('日付'!$E$2-WEEKDAY('日付'!$E$2,2)+41),"") | U57: =IF(DAY('日付'!$E$2-WEEKDAY('日付'!$E$2,2)+42)>14,DAY('日付'!$E$2-WEEKDAY('日付'!$E$2,2)+42),"") | Y57: =IF(DAY('日付'!$F$2-WEEKDAY('日付'!$F$2,2)+36)>14,DAY('日付'!$F$2-WEEKDAY('日付'!$F$2,2)+36),"") | Z57: =IF(DAY('日付'!$F$2-WEEKDAY('日付'!$F$2,2)+37)>14,DAY('日付'!$F$2-WEEKDAY('日付'!$F$2,2)+37),"") | AA57: =IF(DAY('日付'!$F$2-WEEKDAY('日付'!$F$2,2)+38)>14,DAY('日付'!$F$2-WEEKDAY('日付'!$F$2,2)+38),"") | AB57: =IF(DAY('日付'!$F$2-WEEKDAY('日付'!$F$2,2)+39)>14,DAY('日付'!$F$2-WEEKDAY('日付'!$F$2,2)+39),"") | AC57: =IF(DAY('日付'!$F$2-WEEKDAY('日付'!$F$2,2)+40)>14,DAY('日付'!$F$2-WEEKDAY('日付'!$F$2,2)+40),"") | AD57: =IF(DAY('日付'!$F$2-WEEKDAY('日付'!$F$2,2)+41)>14,DAY('日付'!$F$2-WEEKDAY('日付'!$F$2,2)+41),"") | AE57: =IF(DAY('日付'!$F$2-WEEKDAY('日付'!$F$2,2)+42)>14,DAY('日付'!$F$2-WEEKDAY('日付'!$F$2,2)+42),"")
B58: =MONTH('日付'!A1+(7-WEEKDAY('日付'!A1,2)+1)) -> 5 | D58: 月 | E58: 今日の一言：
B61: =DAY('日付'!A1+(7-WEEKDAY('日付'!A1,2)+1)) -> 17
AB62: 利損：
AG63: =IFERROR(VLOOKUP('日付'!A1+(7-WEEKDAY('日付'!A1,2)+1),'祝日一覧'!A:B,2,false),"")
B64: =MONTH('日付'!A1+(7-WEEKDAY('日付'!A1,2)+2)) -> 5 | D64: 火 | E64: 今日の一言：
B67: =DAY('日付'!A1+(7-WEEKDAY('日付'!A1,2)+2)) -> 18
AB68: 利損：
AG69: =IFERROR(VLOOKUP('日付'!A1+(7-WEEKDAY('日付'!A1,2)+2),'祝日一覧'!A:B,2,false),"")
B70: =MONTH('日付'!A1+(7-WEEKDAY('日付'!A1,2)+3)) -> 5 | D70: 水 | E70: 今日の一言：
B73: =DAY('日付'!A1+(7-WEEKDAY('日付'!A1,2)+3)) -> 19
AB74: 利損：
AG75: =IFERROR(VLOOKUP('日付'!A1+(7-WEEKDAY('日付'!A1,2)+3),'祝日一覧'!A:B,2,false),"")
B76: =MONTH('日付'!A1+(7-WEEKDAY('日付'!A1,2)+4)) -> 5 | D76: 木 | E76: 今日の一言：
...

Sheet Daily
A2: =MONTH(TODAY()) -> 1 | B2: 月 | C2: =DAY(TODAY()) -> 7 | D2: 日 | F2: ( | G2: =TEXT(WEEKDAY(TODAY()),"ddd") -> Wed | H2: )
D4: 行動予定 | L4: 理想/結果 | Q4: ↓ | S4: ABC | W4: Routin | AD4: Time
A5: 5
A7: 6
A9: 7
A11: 8
A13: 9
A15: 10
A17: 11
A19: 12
A21: 13
Q22: ↓ | S22: ABC | W22: Prioritized Task List | AD22: Time
A23: 14
A25: 15
A27: 16
A29: 17
A31: 18
A33: 19
A35: 20
A37: 21
A39: 22
A41: 23
A43: 24
A47: 今日のセルフトーク(アファメーション)
A56: 今日一日で得たい結果(1日が終わったときの理想の状態、および得たい結果)
A63: Memo
A77: 昨日のよかったこと・気づいたこと
A83: 昨日をもう一度やり直せるのなら

Sheet Weekly(H)_old
B2: 週間目標 | F2: 今月のテーマ
B5: ルーティーン行動 | O5: 月 | P5: 火 | Q5: 水 | R5: 木 | S5: 金 | T5: 土 | U5: 日 | W5: □
B6: 1
B7: 2 | W7: □
B8: 3
B9: 4 | W9: □
B10: 5
B11: 6 | W11: □
W13: □
B15: 役割と重点タスク
B16: 役割1：
B17: 目標1：身体 | R17: 目標2：社会・情緒
B20: 目標3：知性 | R20: 目標4：精神
B24: 役割2：
B25: 目標1： | R25: 目標2：
B28: 目標3： | R28: 目標4：
B32: 役割3：
B33: 目標1： | R33: 目標2：
B36: 目標3： | R36: 目標4：
B40: 今週の振り返り
B41: 良かったこと | R41: 課題・改善
C52: =MONTH('日付'!$D$2) -> 4 | E52: =IF(DAY('日付'!$D$2-WEEKDAY('日付'!$D$2,2)+1)<=7,DAY('日付'!$D$2-WEEKDAY('日付'!$D$2,2)+1),"") | F52: =IF(DAY('日付'!$D$2-WEEKDAY('日付'!$D$2,2)+2)<=7,DAY('日付'!$D$2-WEEKDAY('日付'!$D$2,2)+2),"") | G52: =IF(DAY('日付'!$D$2-WEEKDAY('日付'!$D$2,2)+3)<=7,DAY('日付'!$D$2-WEEKDAY('日付'!$D$2,2)+3),"") | H52: =IF(DAY('日付'!$D$2-WEEKDAY('日付'!$D$2,2)+4)<=7,DAY('日付'!$D$2-WEEKDAY('日付'!$D$2,2)+4),"") -> 1 | I52: =IF(DAY('日付'!$D$2-WEEKDAY('日付'!$D$2,2)+5)<=7,DAY('日付'!$D$2-WEEKDAY('日付'!$D$2,2)+5),"") -> 2 | J52: =IF(DAY('日付'!$D$2-WEEKDAY('日付'!$D$2,2)+6)<=7,DAY('日付'!$D$2-WEEKDAY('日付'!$D$2,2)+6),"") -> 3 | K52: =IF(DAY('日付'!$D$2-WEEKDAY('日付'!$D$2,2)+7)<=7,DAY('日付'!$D$2-WEEKDAY('日付'!$D$2,2)+7),"") -> 4 | M52: =MONTH('日付'!$E$2) -> 5 | O52: =IF(DAY('日付'!$E$2-WEEKDAY('日付'!$E$2,2)+1)<=7,DAY('日付'!$E$2-WEEKDAY('日付'!$E$2,2)+1),"") | P52: =IF(DAY('日付'!$E$2-WEEKDAY('日付'!$E$2,2)+2)<=7,DAY('日付'!$E$2-WEEKDAY('日付'!$E$2,2)+2),"") | Q52: =IF(DAY('日付'!$E$2-WEEKDAY('日付'!$E$2,2)+3)<=7,DAY('日付'!$E$2-WEEKDAY('日付'!$E$2,2)+3),"") | R52: =IF(DAY('日付'!$E$2-WEEKDAY('日付'!$E$2,2)+4)<=7,DAY('日付'!$E$2-WEEKDAY('日付'!$E$2,2)+4),"") | S52: =IF(DAY('日付'!$E$2-WEEKDAY('日付'!$E$2,2)+5)<=7,DAY('日付'!$E$2-WEEKDAY('日付'!$E$2,2)+5),"") | T52: =IF(DAY('日付'!$E$2-WEEKDAY('日付'!$E$2,2)+6)<=7,DAY('日付'!$E$2-WEEKDAY('日付'!$E$2,2)+6),"") -> 1 | U52: =IF(DAY('日付'!$E$2-WEEKDAY('日付'!$E$2,2)+7)<=7,DAY('日付'!$E$2-WEEKDAY('日付'!$E$2,2)+7),"") -> 2 | W52: =MONTH('日付'!$F$2) -> 6 | Y52: =IF(DAY('日付'!$F$2-WEEKDAY('日付'!$F$2,2)+1)<=7,DAY('日付'!$F$2-WEEKDAY('日付'!$F$2,2)+1),"") | Z52: =IF(DAY('日付'!$F$2-WEEKDAY('日付'!$F$2,2)+2)<=7,DAY('日付'!$F$2-WEEKDAY('日付'!$F$2,2)+2),"") -> 1 | AA52: =IF(DAY('日付'!$F$2-WEEKDAY('日付'!$F$2,2)+3)<=7,DAY('日付'!$F$2-WEEKDAY('日付'!$F$2,2)+3),"") -> 2 | AB52: =IF(DAY('日付'!$F$2-WEEKDAY('日付'!$F$2,2)+4)<=7,DAY('日付'!$F$2-WEEKDAY('日付'!$F$2,2)+4),"") -> 3 | AC52: =IF(DAY('日付'!$F$2-WEEKDAY('日付'!$F$2,2)+5)<=7,DAY('日付'!$F$2-WEEKDAY('日付'!$F$2,2)+5),"") -> 4 | AD52: =IF(DAY('日付'!$F$2-WEEKDAY('日付'!$F$2,2)+6)<=7,DAY('日付'!$F$2-WEEKDAY('日付'!$F$2,2)+6),"") -> 5 | AE52: =IF(DAY('日付'!$F$2-WEEKDAY('日付'!$F$2,2)+7)<=7,DAY('日付'!$F$2-WEEKDAY('日付'!$F$2,2)+7),"") -> 6
E53: =DAY('日付'!$D$2-WEEKDAY('日付'!$D$2,2)+8) -> 5 | F53: =DAY('日付'!$D$2-WEEKDAY('日付'!$D$2,2)+9) -> 6 | G53: =DAY('日付'!$D$2-WEEKDAY('日付'!$D$2,2)+10) -> 7 | H53: =DAY('日付'!$D$2-WEEKDAY('日付'!$D$2,2)+11) -> 8 | I53: =DAY('日付'!$D$2-WEEKDAY('日付'!$D$2,2)+12) -> 9 | J53: =DAY('日付'!$D$2-WEEKDAY('日付'!$D$2,2)+13) -> 10 | K53: =DAY('日付'!$D$2-WEEKDAY('日付'!$D$2,2)+14) -> 11 | O53: =DAY('日付'!$E$2-WEEKDAY('日付'!$E$2,2)+8) -> 3 | P53: =DAY('日付'!$E$2-WEEKDAY('日付'!$E$2,2)+9) -> 4 | Q53: =DAY('日付'!$E$2-WEEKDAY('日付'!$E$2,2)+10) -> 5 | R53: =DAY('日付'!$E$2-WEEKDAY('日付'!$E$2,2)+11) -> 6 | S53: =DAY('日付'!$E$2-WEEKDAY('日付'!$E$2,2)+12) -> 7 | T53: =DAY('日付'!$E$2-WEEKDAY('日付'!$E$2,2)+13) -> 8 | U53: =DAY('日付'!$E$2-WEEKDAY('日付'!$E$2,2)+14) -> 9 | Y53: =DAY('日付'!$F$2-WEEKDAY('日付'!$F$2,2)+8) -> 7 | Z53: =DAY('日付'!$F$2-WEEKDAY('日付'!$F$2,2)+9) -> 8 | AA53: =DAY('日付'!$F$2-WEEKDAY('日付'!$F$2,2)+10) -> 9 | AB53: =DAY('日付'!$F$2-WEEKDAY('日付'!$F$2,2)+11) -> 10 | AC53: =DAY('日付'!$F$2-WEEKDAY('日付'!$F$2,2)+12) -> 11 | AD53: =DAY('日付'!$F$2-WEEKDAY('日付'!$F$2,2)+13) -> 12 | AE53: =DAY('日付'!$F$2-WEEKDAY('日付'!$F$2,2)+14) -> 13
E54: =DAY('日付'!$D$2-WEEKDAY('日付'!$D$2,2)+15) -> 12 | F54: =DAY('日付'!$D$2-WEEKDAY('日付'!$D$2,2)+16) -> 13 | G54: =DAY('日付'!$D$2-WEEKDAY('日付'!$D$2,2)+17) -> 14 | H54: =DAY('日付'!$D$2-WEEKDAY('日付'!$D$2,2)+18) -> 15 | I54: =DAY('日付'!$D$2-WEEKDAY('日付'!$D$2,2)+19) -> 16 | J54: =DAY('日付'!$D$2-WEEKDAY('日付'!$D$2,2)+20) -> 17 | K54: =DAY('日付'!$D$2-WEEKDAY('日付'!$D$2,2)+21) -> 18 | O54: =DAY('日付'!$E$2-WEEKDAY('日付'!$E$2,2)+15) -> 10 | P54: =DAY('日付'!$E$2-WEEKDAY('日付'!$E$2,2)+16) -> 11 | Q54: =DAY('日付'!$E$2-WEEKDAY('日付'!$E$2,2)+17) -> 12 | R54: =DAY('日付'!$E$2-WEEKDAY('日付'!$E$2,2)+18) -> 13 | S54: =DAY('日付'!$E$2-WEEKDAY('日付'!$E$2,2)+19) -> 14 | T54: =DAY('日付'!$E$2-WEEKDAY('日付'!$E$2,2)+20) -> 15 | U54: =DAY('日付'!$E$2-WEEKDAY('日付'!$E$2,2)+21) -> 16 | Y54: =DAY('日付'!$F$2-WEEKDAY('日付'!$F$2,2)+15) -> 14 | Z54: =DAY('日付'!$F$2-WEEKDAY('日付'!$F$2,2)+16) -> 15 | AA54: =DAY('日付'!$F$2-WEEKDAY('日付'!$F$2,2)+17) -> 16 | AB54: =DAY('日付'!$F$2-WEEKDAY('日付'!$F$2,2)+18) -> 17 | AC54: =DAY('日付'!$F$2-WEEKDAY('日付'!$F$2,2)+19) -> 18 | AD54: =DAY('日付'!$F$2-WEEKDAY('日付'!$F$2,2)+20) -> 19 | AE54: =DAY('日付'!$F$2-WEEKDAY('日付'!$F$2,2)+21) -> 20
E55: =DAY('日付'!$D$2-WEEKDAY('日付'!$D$2,2)+22) -> 19 | F55: =DAY('日付'!$D$2-WEEKDAY('日付'!$D$2,2)+23) -> 20 | G55: =DAY('日付'!$D$2-WEEKDAY('日付'!$D$2,2)+24) -> 21 | H55: =DAY('日付'!$D$2-WEEKDAY('日付'!$D$2,2)+25) -> 22 | I55: =DAY('日付'!$D$2-WEEKDAY('日付'!$D$2,2)+26) -> 23 | J55: =DAY('日付'!$D$2-WEEKDAY('日付'!$D$2,2)+27) -> 24 | K55: =DAY('日付'!$D$2-WEEKDAY('日付'!$D$2,2)+28) -> 25 | O55: =DAY('日付'!$E$2-WEEKDAY('日付'!$E$2,2)+22) -> 17 | P55: =DAY('日付'!$E$2-WEEKDAY('日付'!$E$2,2)+23) -> 18 | Q55: =DAY('日付'!$E$2-WEEKDAY('日付'!$E$2,2)+24) -> 19 | R55: =DAY('日付'!$E$2-WEEKDAY('日付'!$E$2,2)+25) -> 20 | S55: =DAY('日付'!$E$2-WEEKDAY('日付'!$E$2,2)+26) -> 21 | T55: =DAY('日付'!$E$2-WEEKDAY('日付'!$E$2,2)+27) -> 22 | U55: =DAY('日付'!$E$2-WEEKDAY('日付'!$E$2,2)+28) -> 23 | Y55: =DAY('日付'!$F$2-WEEKDAY('日付'!$F$2,2)+22) -> 21 | Z55: =DAY('日付'!$F$2-WEEKDAY('日付'!$F$2,2)+23) -> 22 | AA55: =DAY('日付'!$F$2-WEEKDAY('日付'!$F$2,2)+24) -> 23 | AB55: =DAY('日付'!$F$2-WEEKDAY('日付'!$F$2,2)+25) -> 24 | AC55: =DAY('日付'!$F$2-WEEKDAY('日付'!$F$2,2)+26) -> 25 | AD55: =DAY('日付'!$F$2-WEEKDAY('日付'!$F$2,2)+27) -> 26 | AE55: =DAY('日付'!$F$2-WEEKDAY('日付'!$F$2,2)+28) -> 27
E56: =IF(DAY('日付'!$D$2-WEEKDAY('日付'!$D$2,2)+29)>7,DAY('日付'!$D$2-WEEKDAY('日付'!$D$2,2)+29),"") -> 26 | F56: =IF(DAY('日付'!$D$2-WEEKDAY('日付'!$D$2,2)+30)>7,DAY('日付'!$D$2-WEEKDAY('日付'!$D$2,2)+30),"") -> 27 | G56: =IF(DAY('日付'!$D$2-WEEKDAY('日付'!$D$2,2)+31)>7,DAY('日付'!$D$2-WEEKDAY('日付'!$D$2,2)+31),"") -> 28 | H56: =IF(DAY('日付'!$D$2-WEEKDAY('日付'!$D$2,2)+32)>7,DAY('日付'!$D$2-WEEKDAY('日付'!$D$2,2)+32),"") -> 29 | I56: =IF(DAY('日付'!$D$2-WEEKDAY('日付'!$D$2,2)+33)>7,DAY('日付'!$D$2-WEEKDAY('日付'!$D$2,2)+33),"") -> 30 | J56: =IF(DAY('日付'!$D$2-WEEKDAY('日付'!$D$2,2)+34)>7,DAY('日付'!$D$2-WEEKDAY('日付'!$D$2,2)+34),"") | K56: =IF(DAY('日付'!$D$2-WEEKDAY('日付'!$D$2,2)+35)>7,DAY('日付'!$D$2-WEEKDAY('日付'!$D$2,2)+35),"") | O56: =IF(DAY('日付'!$E$2-WEEKDAY('日付'!$E$2,2)+29)>7,DAY('日付'!$E$2-WEEKDAY('日付'!$E$2,2)+29),"") -> 24 | P56: =IF(DAY('日付'!$E$2-WEEKDAY('日付'!$E$2,2)+30)>7,DAY('日付'!$E$2-WEEKDAY('日付'!$E$2,2)+30),"") -> 25 | Q56: =IF(DAY('日付'!$E$2-WEEKDAY('日付'!$E$2,2)+31)>7,DAY('日付'!$E$2-WEEKDAY('日付'!$E$2,2)+31),"") -> 26 | R56: =IF(DAY('日付'!$E$2-WEEKDAY('日付'!$E$2,2)+32)>7,DAY('日付'!$E$2-WEEKDAY('日付'!$E$2,2)+32),"") -> 27 | S56: =IF(DAY('日付'!$E$2-WEEKDAY('日付'!$E$2,2)+33)>7,DAY('日付'!$E$2-WEEKDAY('日付'!$E$2,2)+33),"") -> 28 | T56: =IF(DAY('日付'!$E$2-WEEKDAY('日付'!$E$2,2)+34)>7,DAY('日付'!$E$2-WEEKDAY('日付'!$E$2,2)+34),"") -> 29 | U56: =IF(DAY('日付'!$E$2-WEEKDAY('日付'!$E$2,2)+35)>7,DAY('日付'!$E$2-WEEKDAY('日付'!$E$2,2)+35),"") -> 30 | Y56: =IF(DAY('日付'!$F$2-WEEKDAY('日付'!$F$2,2)+29)>7,DAY('日付'!$F$2-WEEKDAY('日付'!$F$2,2)+29),"") -> 28 | Z56: =IF(DAY('日付'!$F$2-WEEKDAY('日付'!$F$2,2)+30)>7,DAY('日付'!$F$2-WEEKDAY('日付'!$F$2,2)+30),"") -> 29 | AA56: =IF(DAY('日付'!$F$2-WEEKDAY('日付'!$F$2,2)+31)>7,DAY('日付'!$F$2-WEEKDAY('日付'!$F$2,2)+31),"") -> 30 | AB56: =IF(DAY('日付'!$F$2-WEEKDAY('日付'!$F$2,2)+32)>7,DAY('日付'!$F$2-WEEKDAY('日付'!$F$2,2)+32),"") | AC56: =IF(DAY('日付'!$F$2-WEEKDAY('日付'!$F$2,2)+33)>7,DAY('日付'!$F$2-WEEKDAY('日付'!$F$2,2)+33),"") | AD56: =IF(DAY('日付'!$F$2-WEEKDAY('日付'!$F$2,2)+34)>7,DAY('日付'!$F$2-WEEKDAY('日付'!$F$2,2)+34),"") | AE56: =IF(DAY('日付'!$F$2-WEEKDAY('日付'!$F$2,2)+35)>7,DAY('日付'!$F$2-WEEKDAY('日付'!$F$2,2)+35),"")
E57: =IF(DAY('日付'!$D$2-WEEKDAY('日付'!$D$2,2)+36)>14,DAY('日付'!$D$2-WEEKDAY('日付'!$D$2,2)+36),"") | F57: =IF(DAY('日付'!$D$2-WEEKDAY('日付'!$D$2,2)+37)>14,DAY('日付'!$D$2-WEEKDAY('日付'!$D$2,2)+37),"") | G57: =IF(DAY('日付'!$D$2-WEEKDAY('日付'!$D$2,2)+38)>14,DAY('日付'!$D$2-WEEKDAY('日付'!$D$2,2)+38),"") | H57: =IF(DAY('日付'!$D$2-WEEKDAY('日付'!$D$2,2)+39)>14,DAY('日付'!$D$2-WEEKDAY('日付'!$D$2,2)+39),"") | I57: =IF(DAY('日付'!$D$2-WEEKDAY('日付'!$D$2,2)+40)>14,DAY('日付'!$D$2-WEEKDAY('日付'!$D$2,2)+40),"") | J57: =IF(DAY('日付'!$D$2-WEEKDAY('日付'!$D$2,2)+41)>14,DAY('日付'!$D$2-WEEKDAY('日付'!$D$2,2)+41),"") | K57: =IF(DAY('日付'!$D$2-WEEKDAY('日付'!$D$2,2)+42)>14,DAY('日付'!$D$2-WEEKDAY('日付'!$D$2,2)+42),"") | O57: =IF(DAY('日付'!$E$2-WEEKDAY('日付'!$E$2,2)+36)>14,DAY('日付'!$E$2-WEEKDAY('日付'!$E$2,2)+36),"") -> 31 | P57: =IF(DAY('日付'!$E$2-WEEKDAY('日付'!$E$2,2)+37)>14,DAY('日付'!$E$2-WEEKDAY('日付'!$E$2,2)+37),"") | Q57: =IF(DAY('日付'!$E$2-WEEKDAY('日付'!$E$2,2)+38)>14,DAY('日付'!$E$2-WEEKDAY('日付'!$E$2,2)+38),"") | R57: =IF(DAY('日付'!$E$2-WEEKDAY('日付'!$E$2,2)+39)>14,DAY('日付'!$E$2-WEEKDAY('日付'!$E$2,2)+39),"") | S57: =IF(DAY('日付'!$E$2-WEEKDAY('日付'!$E$2,2)+40)>14,DAY('日付'!$E$2-WEEKDAY('日付'!$E$2,2)+40),"") | T57: =IF(DAY('日付'!$E$2-WEEKDAY('日付'!$E$2,2)+41)>14,DAY('日付'!$E$2-WEEKDAY('日付'!$E$2,2)+41),"") | U57: =IF(DAY('日付'!$E$2-WEEKDAY('日付'!$E$2,2)+42)>14,DAY('日付'!$E$2-WEEKDAY('日付'!$E$2,2)+42),"") | Y57: =IF(DAY('日付'!$F$2-WEEKDAY('日付'!$F$2,2)+36)>14,DAY('日付'!$F$2-WEEKDAY('日付'!$F$2,2)+36),"") | Z57: =IF(DAY('日付'!$F$2-WEEKDAY('日付'!$F$2,2)+37)>14,DAY('日付'!$F$2-WEEKDAY('日付'!$F$2,2)+37),"") | AA57: =IF(DAY('日付'!$F$2-WEEKDAY('日付'!$F$2,2)+38)>14,DAY('日付'!$F$2-WEEKDAY('日付'!$F$2,2)+38),"") | AB57: =IF(DAY('日付'!$F$2-WEEKDAY('日付'!$F$2,2)+39)>14,DAY('日付'!$F$2-WEEKDAY('日付'!$F$2,2)+39),"") | AC57: =IF(DAY('日付'!$F$2-WEEKDAY('日付'!$F$2,2)+40)>14,DAY('日付'!$F$2-WEEKDAY('日付'!$F$2,2)+40),"") | AD57: =IF(DAY('日付'!$F$2-WEEKDAY('日付'!$F$2,2)+41)>14,DAY('日付'!$F$2-WEEKDAY('日付'!$F$2,2)+41),"") | AE57: =IF(DAY('日付'!$F$2-WEEKDAY('日付'!$F$2,2)+42)>14,DAY('日付'!$F$2-WEEKDAY('日付'!$F$2,2)+42),"")
B58: =MONTH('日付'!A1+(7-WEEKDAY('日付'!A1,2)+1)) -> 5 | D58: 月 | E58: 今日の一言：
B61: =DAY('日付'!A1+(7-WEEKDAY('日付'!A1,2)+1)) -> 17
AB62: 利損：
AG63: =IFERROR(VLOOKUP('日付'!A1+(7-WEEKDAY('日付'!A1,2)+1),'祝日一覧'!A:B,2,false),"")
B64: =MONTH('日付'!A1+(7-WEEKDAY('日付'!A1,2)+2)) -> 5 | D64: 火 | E64: 今日の一言：
B67: =DAY('日付'!A1+(7-WEEKDAY('日付'!A1,2)+2)) -> 18
AB68: 利損：
AG69: =IFERROR(VLOOKUP('日付'!A1+(7-WEEKDAY('日付'!A1,2)+2),'祝日一覧'!A:B,2,false),"")
B70: =MONTH('日付'!A1+(7-WEEKDAY('日付'!A1,2)+3)) -> 5 | D70: 水 | E70: 今日の一言：
B73: =DAY('日付'!A1+(7-WEEKDAY('日付'!A1,2)+3)) -> 19
AB74: 利損：
AG75: =IFERROR(VLOOKUP('日付'!A1+(7-WEEKDAY('日付'!A1,2)+3),'祝日一覧'!A:B,2,false),"")
B76: =MONTH('日付'!A1+(7-WEEKDAY('日付'!A1,2)+4)) -> 5 | D76: 木 | E76: 今日の一言：
...

Sheet 目標設定
A2: 価値観/ミッション/役割(なぜ？)
A12: 目標(何を？/いつ？)
A23: 優先度 | D23: ステップ/どのように？ | AB23: 期限
A49: 価値観/ミッション/役割(なぜ？)
A59: 目標(何を？/いつ？)
A70: 優先度 | D70: ステップ/どのように？ | AB70: 期限

Sheet 5ヵ年計画
B2: 5ヵ年計画
F4: ビジネス (仕事、収入、地位、人間関係、能力等の状態) | T4: プライベート (住居、家族、余暇時間、地域社会との関係等の状態)
B13: 1年後 ( 歳)
B29: 3年後 ( 歳)
B45: 5年後 ( 歳)
B56: ブレイクダウン

Sheet 年間目標
B4: 目標：
B8: フェーズ | G8: 詳細 | I8: 第 1 四半期 | X8: 第 2 四半期
I9: 1 月 | N9: 2 月 | S9: 3 月 | X9: 4 月 | AC9: 5 月 | AH9: 6 月
D10: プロジェクトの週: | G10: 各月の最初の月曜日の 日付を入力します -->
B11: 1 | G11: -
G12: -
G13: -
G14: -
G15: -
B17: 2 | G17: -
G18: -
G19: -
G20: -
G21: -
G22: -
B23: 3 | G23: -
G24: -
G25: -
G26: -
G27: -
G28: -
B29: 4 | G29: -
G30: -
G31: -
G32: -
G33: -
G34: -
B35: 5 | G35: -
G36: -
G37: -
G38: -
G39: -
G40: -
B44: 目標：
B48: フェーズ | G48: 詳細 | I48: 第 3 四半期 | X48: 第 4 四半期
I49: 7 月 | N49: 8 月 | S49: 9 月 | X49: 10 月 | AC49: 11 月 | AH49: 12 月
D50: プロジェクトの週: | G50: 各月の最初の月曜日の 日付を入力します -->
B51: 1 | G51: -
G52: -
G53: -
...

Sheet 4半期目標
B4: 目標：
B8: WBS 番号 | C8: タスクのタイトル | D8: 開始日 | E8: 期限
F9: 第 1 週 | K9: 第 2 週 | P9: 第 3 週 | U9: 第 4 週 | Z9: 第 5 週 | AE9: 第 6 週 | AJ9: 第 7 週 | AO9: 第 8 週 | AT9: 第 9 週 | AY9: 第 10 週 | BD9: 第 11 週 | BI9: 第 12 週
F10: 月 | G10: 火 | H10: 水 | I10: 木 | J10: 金 | K10: 月 | L10: 火 | M10: 水 | N10: 木 | O10: 金 | P10: 月 | Q10: 火 | R10: 水 | S10: 木 | T10: 金 | U10: 月 | V10: 火 | W10: 水 | X10: 木 | Y10: 金 | Z10: 月 | AA10: 火 | AB10: 水 | AC10: 木 | AD10: 金 | AE10: 月 | AF10: 火 | AG10: 水 | AH10: 木 | AI10: 金 | AJ10: 月 | AK10: 火 | AL10: 水 | AM10: 木 | AN10: 金 | AO10: 月 | AP10: 火 | AQ10: 水 | AR10: 木 | AS10: 金 | AT10: 月 | AU10: 火 | AV10: 水 | AW10: 木 | AX10: 金 | AY10: 月 | AZ10: 火 | BA10: 水 | BB10: 木 | BC10: 金 | BD10: 月 | BE10: 火 | BF10: 水 | BG10: 木 | BH10: 金 | BI10: 月 | BJ10: 火 | BK10: 水 | BL10: 木 | BM10: 金
B11: 1
B12: 1.1
B13: 1.2
B14: 1.3
B15: 1.4
B16: 1.5
B17: 1.6
B18: 2
B19: 2.1
B20: 2.2
B21: 2.3
B22: 2.4
... B52: 6.6
B58: 目標：
B62: WBS 番号 | C62: タスクのタイトル | D62: 開始日 | E62: 期限
F63: 第 1 週 | K63: 第 2 週 | P63: 第 3 週 | U63: 第 4 週 | Z63: 第 5 週 | AE63: 第 6 週 | AJ63: 第 7 週 | AO63: 第 8 週 | AT63: 第 9 週 | AY63: 第 10 週 | BD63: 第 11 週 | BI63: 第 12 週
F64: 月 | G64: 火 | H64: 水 | I64: 木 | J64: 金 | K64: 月 | L64: 火 | M64: 水 | N64: 木 | O64: 金 | P64: 月 | Q64: 火 | R64: 水 | S64: 木 | T64: 金 | U64: 月 | V64: 火 | W64: 水 | X64: 木 | Y64: 金 | Z64: 月 | AA64: 火 | AB64: 水 | AC64: 木 | AD64: 金 | AE64: 月 | AF64: 火 | AG64: 水 | AH64: 木 | AI64: 金 | AJ64: 月 | AK64: 火 | AL64: 水 | AM64: 木 | AN64: 金 | AO64: 月 | AP64: 火 | AQ64: 水 | AR64: 木 | AS64: 金 | AT64: 月 | AU64: 火 | AV64: 水 | AW64: 木 | AX64: 金 | AY64: 月 | AZ64: 火 | BA64: 水 | BB64: 木 | BC64: 金 | BD64: 月 | BE64: 火 | BF64: 水 | BG64: 木 | BH64: 金 | BI64: 月 | BJ64: 火 | BK64: 水 | BL64: 木 | BM64: 金
B65: 1
B66: 1.1
B67: 1.2
B68: 1.3
B69: 1.4
B70: 1.5
B71: 1.6
B72: 2
B73: 2.1
B74: 2.2
B75: 2.3
B76: 2.4
... B106: 6.6

Sheet Inbox
A2: Inbox | D2: 欲しい(w)、買う(b)、やりたい(d)、行きたい(g)
D3: メモ(N)、言葉(Q)、考え(I)、価値観(V)、習慣(H)
A4: 処理 | C4: Cat
A5: □
A7: □
A9: □
A11: □
A13: □
A15: □
A17: □
A19: □
A21: □
A23: □
A25: □
A27: □
... A57: □
A60: Inbox | D60: 欲しい(w)、買う(b)、やりたい(d)、行きたい(g)
D61: メモ(N)、言葉(Q)、考え(I)、価値観(V)、習慣(H)
A62: 処理 | C62: Cat
A63: □
A65: □
A67: □
A69: □
A71: □
A73: □
A75: □
A77: □
A79: □
A81: □
A83: □
A85: □
... A115: □

Sheet FuturePaging

Sheet トレード日誌
B2: 日時： | M2: 通貨ペア：
B4: 日足： 25 ・ 75 ・ 200 | Z4: 4時間： 25 ・ 75 ・ 200
C5: ローソク足： | AA5: ローソク足：
B6: 1時間： 25 ・ 75 ・ 200 | Z6: 15分： 25 ・ 75 ・ 200
C7: ローソク足： | AA7: ローソク足：
B9: en： | I9: long ・ short | P9: lot： | V9: tp： | AD9: sl：
B10: エントリー根拠：
B13: 結果：
B15: コメント、振り返り：
B18: 日時： | M18: 通貨ペア：
B20: 日足： 25 ・ 75 ・ 200 | Z20: 4時間： 25 ・ 75 ・ 200
C21: ローソク足： | AA21: ローソク足：
B22: 1時間： 25 ・ 75 ・ 200 | Z22: 15分： 25 ・ 75 ・ 200
C23: ローソク足： | AA23: ローソク足：
B25: en： | I25: long ・ short | P25: lot： | V25: tp： | AD25: sl：
B26: エントリー根拠：
B29: 結果：
B31: コメント、振り返り：
B34: 日時： | M34: 通貨ペア：
B36: 日足： 25 ・ 75 ・ 200 | Z36: 4時間： 25 ・ 75 ・ 200
C37: ローソク足： | AA37: ローソク足：
B38: 1時間： 25 ・ 75 ・ 200 | Z38: 15分： 25 ・ 75 ・ 200
C39: ローソク足： | AA39: ローソク足：
B41: en： | I41: long ・ short | P41: lot： | V41: tp： | AD41: sl：
B42: エントリー根拠：
B45: 結果：
B47: コメント、振り返り：
B50: 日時： | M50: 通貨ペア：
B52: 日足： 25 ・ 75 ・ 200 | Z52: 4時間： 25 ・ 75 ・ 200
C53: ローソク足： | AA53: ローソク足：
B54: 1時間： 25 ・ 75 ・ 200 | Z54: 15分： 25 ・ 75 ・ 200
C55: ローソク足： | AA55: ローソク足：
B57: en： | I57: long ・ short | P57: lot： | V57: tp： | AD57: sl：
B58: エントリー根拠：
B61: 結果：
B63: コメント、振り返り：
B66: 日時： | M66: 通貨ペア：
B68: 日足： 25 ・ 75 ・ 200 | Z68: 4時間： 25 ・ 75 ・ 200
C69: ローソク足： | AA69: ローソク足：
B70: 1時間： 25 ・ 75 ・ 200 | Z70: 15分： 25 ・ 75 ・ 200
...

Sheet 約束
B2: Promise List
A4: 処理 | C4: 誰と | G4: 何を？ | U4: 処理 | W4: 誰と | AA4: 何を？
A5: □ | U5: □
A7: □ | U7: □
A9: □ | U9: □
A11: □ | U11: □
A13: □ | U13: □
A15: □ | U15: □
A17: □ | U17: □
A19: □ | U19: □
A21: □ | U21: □
A23: □ | U23: □
A25: □ | U25: □
A27: □ | U27: □
... A61: □ | U61: □
B65: Promise List
A67: 処理 | C67: 誰と | G67: 何を？ | U67: 処理 | W67: 誰と | AA67: 何を？
A68: □ | U68: □
A70: □ | U70: □
A72: □ | U72: □
A74: □ | U74: □
A76: □ | U76: □
A78: □ | U78: □
A80: □ | U80: □
A82: □ | U82: □
A84: □ | U84: □
A86: □ | U86: □
A88: □ | U88: □
A90: □ | U90: □
... A124: □ | U124: □

Sheet 座右の銘
A2: 心に残る言葉
A4: 誰のコトバ | G4: 座右の銘
A65: 心に残る言葉
A67: 誰のコトバ | G67: 座右の銘

Sheet 読書
B2: 読書
B4: 書名 | V4: 著者名 | AE4: 開始
B6: 学び、行動1 | AE6: メモ、感想
B9: 学び、行動2
B12: 学び、行動3
B16: 書名 | V16: 著者名 | AE16: 開始
B18: 学び、行動1 | AE18: メモ、感想
B21: 学び、行動2
B24: 学び、行動3
B28: 書名 | V28: 著者名 | AE28: 開始
B30: 学び、行動1 | AE30: メモ、感想
B33: 学び、行動2
B36: 学び、行動3
B40: 書名 | V40: 著者名 | AE40: 開始
B42: 学び、行動1 | AE42: メモ、感想
B45: 学び、行動2
B48: 学び、行動3
B52: 書名 | V52: 著者名 | AE52: 開始
B54: 学び、行動1 | AE54: メモ、感想
B57: 学び、行動2
B60: 学び、行動3
B65: 読書
B67: 書名 | V67: 著者名 | AE67: 開始
B69: 学び、行動1 | AE69: メモ、感想
B72: 学び、行動2
B75: 学び、行動3
B79: 書名 | V79: 著者名 | AE79: 開始
B81: 学び、行動1 | AE81: メモ、感想
